Workbook

Sheet DataSheet
A1: Andorra | B1: Advanced | D1: iso3 | E1: continent | G1: iso3 | H1: gdp_per_capita_2022
A2: Australia | B2: Advanced | D2: AFG | E2: Asia | G2: ABW | H2: 30975.999
A3: Austria | B3: Advanced | D3: ALA | E3: Europe | G3: AFE | H3: 1679.3276
A4: Belgium | B4: Advanced | D4: ALB | E4: Europe | G4: AFG | H4: 357.26115
A5: Canada | B5: Advanced | D5: DZA | E5: Africa | G5: AFW | H5: 2138.4731
A6: Croatia | B6: Advanced | D6: ASM | E6: Oceania | G6: AGO | H6: 3682.1132
A7: Cyprus | B7: Advanced | D7: AND | E7: Europe | G7: ALB | H7: 7756.9619
A8: Czech Republic | B8: Advanced | D8: AGO | E8: Africa | G8: AND | H8: 42414.048
A9: Denmark | B9: Advanced | D9: AIA | E9: Americas | G9: ARB | H9: 7950.3558
A10: Estonia | B10: Advanced | D10: ATA | G10: ARE | H10: 50759.759
A11: Finland | B11: Advanced | D11: ATG | E11: Americas | G11: ARG | H11: 13962.189
A12: France | B12: Advanced | D12: ARG | E12: Americas | G12: ARM | H12: 6571.9745
A13: Germany | B13: Advanced | D13: ARM | E13: Asia | G13: ASM | H13: 18017.459
A14: Greece | B14: Advanced | D14: ABW | E14: Americas | G14: ATG | H14: 20105.199
A15: Hong Kong SAR | B15: Advanced | D15: AUS | E15: Oceania | G15: AUS | H15: 65169.519
A16: Iceland | B16: Advanced | D16: AUT | E16: Europe | G16: AUT | H16: 52336.772
A17: Ireland | B17: Advanced | D17: AZE | E17: Asia | G17: AZE | H17: 7770.5942
A18: Israel | B18: Advanced | D18: BHS | E18: Americas | G18: BDI | H18: 302.9925
A19: Italy | B19: Advanced | D19: BHR | E19: Asia | G19: BEL | H19: 50605.75
A20: Japan | B20: Advanced | D20: BGD | E20: Asia | G20: BEN | H20: 1266.4271
A21: Korea | B21: Advanced | D21: BRB | E21: Americas | G21: BFA | H21: 827.33084
A22: Latvia | B22: Advanced | D22: BLR | E22: Europe | G22: BGD | H22: 2716.4859
... A51: The Bahamas | B51: Emerging and Developing | D51: COM | E51: Africa | G51: CSS | H51: 17456.308
A52: Bahrain | B52: Emerging and Developing | D52: COG | E52: Africa | G52: CUB
A53: Bangladesh | B53: Emerging and Developing | D53: COD | E53: Africa | G53: CUW | H53: 20057.141
A54: Barbados | B54: Emerging and Developing | D54: COK | E54: Oceania | G54: CYM | H54: 93030.705
A55: Belarus | B55: Emerging and Developing | D55: CRI | E55: Americas | G55: CYP | H55: 33231.043
A56: Belize | B56: Emerging and Developing | D56: CIV | E56: Africa | G56: CZE | H56: 28282.224
A57: Benin | B57: Emerging and Developing | D57: HRV | E57: Europe | G57: DEU | H57: 50506.518
A58: Bhutan | B58: Emerging and Developing | D58: CUB | E58: Americas | G58: DJI | H58: 3133.2578
A59: Bolivia | B59: Emerging and Developing | D59: CUW | E59: Americas | G59: DMA | H59: 9323.6609
A60: Bosnia and Herzegovina | B60: Emerging and Developing | D60: CYP | E60: Asia | G60: DNK | H60: 67781.094
A61: Botswana | B61: Emerging and Developing | D61: CZE | E61: Europe | G61: DOM | H61: 10104.245
A62: Brazil | B62: Emerging and Developing | D62: DNK | E62: Europe | G62: DZA | H62: 4960.3033
A63: Brunei Darussalam | B63: Emerging and Developing | D63: DJI | E63: Africa | G63: EAP | H63: 10106.994
A64: Bulgaria | B64: Emerging and Developing | D64: DMA | E64: Americas | G64: EAR | H64: 4043.8278
... A70: Central African Republic | B70: Emerging and Developing | D70: ERI | E70: Africa | G70: EMU | H70: 41608.712
A71: Chad | B71: Emerging and Developing | D71: EST | E71: Europe | G71: ERI
A72: Chile | B72: Emerging and Developing | D72: SWZ | E72: Africa | G72: ESP | H72: 30319.499
A73: China | B73: Emerging and Developing | D73: ETH | E73: Africa | G73: EST | H73: 28340.383
...

Sheet Sheet1
A1: iso3 | B1: country | C1: hdi_2000 | D1: hdi_2001 | E1: hdi_2002 | F1: hdi_2003 | G1: hdi_2004 | H1: hdi_2005 | I1: hdi_2006 | J1: hdi_2007 | K1: hdi_2008 | L1: hdi_2009 | M1: hdi_2010 | N1: hdi_2011 | O1: hdi_2012 | P1: hdi_2013 | Q1: hdi_2014 | R1: hdi_2015 | S1: hdi_2016 | T1: hdi_2017 | U1: hdi_2018 | V1: hdi_2019 | W1: hdi_2020 | X1: hdi_2021 | Y1: hdi_2022 | Z1: continents | AA1: economic_status | AB1: N_locked | AD1: N
A2: GNQ | B2: Equatorial Guinea | C2: 0.511 | D2: 0.524 | E2: 0.539 | F2: 0.545 | G2: 0.556 | H2: 0.57 | I2: 0.587 | J2: 0.599 | K2: 0.606 | L2: 0.613 | M2: 0.609 | N2: 0.618 | O2: 0.628 | P2: 0.633 | Q2: 0.639 | R2: 0.648 | S2: 0.65 | T2: 0.65 | U2: 0.652 | V2: 0.653 | W2: 0.65 | X2: 0.647 | Y2: 0.65 | Z2: Africa | AA2: Emerging and Developing | AB2: 4 | AD2: {=_xlfn.SORTBY(_xlfn.SEQUENCE(175), _xlfn.RANDARRAY(175))} -> 172 | AF2: {=_xlfn.UNIQUE(Z2:Z176)} -> Africa | AG2: =COUNTIF($Z$2:$Z$176,AF2) -> 48 | AH2: =(AG2/$AG$9)*150 -> 41.142857 | AI2: =AG2/$AG$9 -> 0.27428571
A3: LBY | B3: Libya | C3: 0.746 | D3: 0.748 | E3: 0.75 | F3: 0.755 | G3: 0.758 | H3: 0.764 | I3: 0.768 | J3: 0.771 | K3: 0.773 | L3: 0.772 | M3: 0.774 | N3: 0.734 | O3: 0.777 | P3: 0.766 | Q3: 0.75 | R3: 0.749 | S3: 0.746 | T3: 0.761 | U3: 0.764 | V3: 0.756 | W3: 0.737 | X3: 0.746 | Y3: 0.746 | Z3: Africa | AA3: Emerging and Developing | AB3: 5 | AD3: 103 | AF3: Asia | AG3: =COUNTIF($Z$2:$Z$176,AF3) -> 44 | AH3: =(AG3/$AG$9)*150 -> 37.714286 | AI3: =AG3/$AG$9 -> 0.25142857 | AM3: Continent | AN3: Number of countries | AO3: Advanced | AP3: Sample size | AQ3: Max Advanced | AR3: E(Advanced)
A4: TGO | B4: Togo | C4: 0.436 | D4: 0.439 | E4: 0.443 | F4: 0.449 | G4: 0.448 | H4: 0.446 | I4: 0.452 | J4: 0.445 | K4: 0.452 | L4: 0.46 | M4: 0.469 | N4: 0.483 | O4: 0.487 | P4: 0.495 | Q4: 0.502 | R4: 0.51 | S4: 0.515 | T4: 0.522 | U4: 0.528 | V4: 0.536 | W4: 0.54 | X4: 0.545 | Y4: 0.547 | Z4: Africa | AA4: Emerging and Developing | AB4: 6 | AD4: 30 | AF4: Australia | AG4: =COUNTIF($Z$2:$Z$176,AF4) -> 1 | AH4: =(AG4/$AG$9)*150 -> 0.85714286 | AI4: =AG4/$AG$9 -> 0.0057142857 | AM4: Africa | AN4: 48 | AO4: 0 | AP4: 41 | AQ4: =MIN(AO4,AP4) -> 0 | AR4: =AP4*AO4/AN4 -> 0
A5: GHA | B5: Ghana | C5: 0.5 | D5: 0.499 | E5: 0.506 | F5: 0.51 | G5: 0.517 | H5: 0.529 | I5: 0.537 | J5: 0.547 | K5: 0.558 | L5: 0.563 | M5: 0.571 | N5: 0.579 | O5: 0.583 | P5: 0.587 | Q5: 0.582 | R5: 0.586 | S5: 0.586 | T5: 0.585 | U5: 0.589 | V5: 0.599 | W5: 0.601 | X5: 0.6 | Y5: 0.602 | Z5: Africa | AA5: Emerging and Developing | AB5: 14 | AD5: 33 | AF5: Europe | AG5: =COUNTIF($Z$2:$Z$176,AF5) -> 40 | AH5: =(AG5/$AG$9)*150 -> 34.285714 | AI5: =AG5/$AG$9 -> 0.22857143 | AM5: Asia | AN5: 44 | AO5: 4 | AP5: 38 | AQ5: =MIN(AO5,AP5) -> 4 | AR5: =AP5*AO5/AN5 -> 3.4545455
A6: ETH | B6: Ethiopia | C6: 0.286 | D6: 0.299 | E6: 0.305 | F6: 0.31 | G6: 0.323 | H6: 0.343 | I6: 0.359 | J6: 0.376 | K6: 0.391 | L6: 0.399 | M6: 0.409 | N6: 0.419 | O6: 0.426 | P6: 0.437 | Q6: 0.445 | R6: 0.455 | S6: 0.465 | T6: 0.472 | U6: 0.479 | V6: 0.485 | W6: 0.489 | X6: 0.489 | Y6: 0.492 | Z6: Africa | AA6: Emerging and Developing | AB6: 17 | AD6: 95 | AF6: North America | AG6: =COUNTIF($Z$2:$Z$176,AF6) -> 21 | AH6: =(AG6/$AG$9)*150 -> 18 | AI6: =AG6/$AG$9 -> 0.12 | AM6: Australia | AN6: 1 | AO6: 1 | AP6: 1 | AQ6: =MIN(AO6,AP6) -> 1 | AR6: =AP6*AO6/AN6 -> 1
A7: TCD | B7: Chad | C7: 0.292 | D7: 0.302 | E7: 0.309 | F7: 0.309 | G7: 0.327 | H7: 0.329 | I7: 0.328 | J7: 0.339 | K7: 0.343 | L7: 0.357 | M7: 0.364 | N7: 0.373 | O7: 0.381 | P7: 0.385 | Q7: 0.392 | R7: 0.388 | S7: 0.388 | T7: 0.389 | U7: 0.393 | V7: 0.398 | W7: 0.396 | X7: 0.393 | Y7: 0.394 | Z7: Africa | AA7: Emerging and Developing | AB7: 19 | AD7: 146 | AF7: Oceania | AG7: =COUNTIF($Z$2:$Z$176,AF7) -> 10 | AH7: =(AG7/$AG$9)*150 -> 8.5714286 | AI7: =AG7/$AG$9 -> 0.057142857 | AM7: Europe | AN7: 40 | AO7: 24 | AP7: 34 | AQ7: =MIN(AO7,AP7) -> 24 | AR7: =AP7*AO7/AN7 -> 20.4
A8: MAR | B8: Morocco | C8: 0.525 | D8: 0.536 | E8: 0.547 | F8: 0.557 | G8: 0.564 | H8: 0.57 | I8: 0.576 | J8: 0.583 | K8: 0.59 | L8: 0.596 | M8: 0.604 | N8: 0.616 | O8: 0.626 | P8: 0.636 | Q8: 0.645 | R8: 0.656 | S8: 0.662 | T8: 0.671 | U8: 0.677 | V8: 0.684 | W8: 0.683 | X8: 0.688 | Y8: 0.698 | Z8: Africa | AA8: Emerging and Developing | AB8: 25 | AD8: 115 | AF8: South America | AG8: =COUNTIF($Z$2:$Z$176,AF8) -> 11 | AH8: =(AG8/$AG$9)*150 -> 9.4285714 | AI8: =AG8/$AG$9 -> 0.062857143 | AM8: North America | AN8: 21 | AO8: 2 | AP8: 18 | AQ8: =MIN(AO8,AP8) -> 2 | AR8: =AP8*AO8/AN8 -> 1.7142857
A9: LSO | B9: Lesotho | C9: 0.456 | D9: 0.452 | E9: 0.449 | F9: 0.45 | G9: 0.448 | H9: 0.447 | I9: 0.444 | J9: 0.45 | K9: 0.453 | L9: 0.457 | M9: 0.47 | N9: 0.478 | O9: 0.489 | P9: 0.494 | Q9: 0.5 | R9: 0.508 | S9: 0.518 | T9: 0.522 | U9: 0.525 | V9: 0.528 | W9: 0.53 | X9: 0.522 | Y9: 0.521 | Z9: Africa | AA9: Emerging and Developing | AB9: 30 | AD9: 15 | AG9: =SUM(AG2:AG8) -> 175 | AH9: =SUM(AH2:AH8) -> 150 | AI9: =SUM(AI2:AI8) -> 1 | AM9: Oceania | AN9: 10 | AO9: 1 | AP9: 9 | AQ9: =MIN(AO9,AP9) -> 1 | AR9: =AP9*AO9/AN9 -> 0.9
A10: SDN | B10: Sudan | C10: 0.42 | D10: 0.428 | E10: 0.434 | F10: 0.438 | G10: 0.441 | H10: 0.448 | I10: 0.466 | J10: 0.472 | K10: 0.48 | L10: 0.489 | M10: 0.489 | N10: 0.491 | O10: 0.498 | P10: 0.503 | Q10: 0.511 | R10: 0.514 | S10: 0.517 | T10: 0.52 | U10: 0.52 | V10: 0.521 | W10: 0.518 | X10: 0.516 | Y10: 0.516 | Z10: Africa | AA10: Emerging and Developing | AB10: 32 | AD10: 75 | AM10: South America | AN10: 11 | AO10: 0 | AP10: 9 | AQ10: =MIN(AO10,AP10) -> 0 | AR10: =AP10*AO10/AN10 -> 0
A11: UGA | B11: Uganda | C11: 0.392 | D11: 0.402 | E11: 0.414 | F11: 0.427 | G11: 0.441 | H11: 0.451 | I11: 0.463 | J11: 0.473 | K11: 0.481 | L11: 0.491 | M11: 0.5 | N11: 0.504 | O11: 0.504 | P11: 0.511 | Q11: 0.518 | R11: 0.525 | S11: 0.531 | T11: 0.534 | U11: 0.539 | V11: 0.544 | W11: 0.545 | X11: 0.545 | Y11: 0.55 | Z11: Africa | AA11: Emerging and Developing | AB11: 33 | AD11: 162 | AF11: {=_xlfn.UNIQUE(Z2:Z176)} -> Africa | AG11: =COUNTIFS($Z$2:$Z$176, AF11, $AA$2:$AA$176, "Advanced") -> 0 | AM11: TOTAL | AN11: =SUM(AN4:AN10) -> 175 | AO11: =SUM(AO4:AO10) -> 32 | AP11: =SUM(AP4:AP10) -> 150 | AQ11: =SUM(AQ4:AQ10) -> 32 | AR11: =SUM(AR4:AR10) -> 27.468831
A12: EGY | B12: Egypt | C12: 0.629 | D12: 0.633 | E12: 0.634 | F12: 0.632 | G12: 0.635 | H12: 0.637 | I12: 0.642 | J12: 0.649 | K12: 0.656 | L12: 0.661 | M12: 0.667 | N12: 0.671 | O12: 0.679 | P12: 0.684 | Q12: 0.688 | R12: 0.695 | S12: 0.702 | T12: 0.709 | U12: 0.717 | V12: 0.724 | W12: 0.729 | X12: 0.726 | Y12: 0.728 | Z12: Africa | AA12: Emerging and Developing | AB12: 34 | AD12: 149 | AF12: Asia | AG12: =COUNTIFS($Z$2:$Z$176, AF12, $AA$2:$AA$176, "Advanced") -> 4
A13: MOZ | B13: Mozambique | C13: 0.303 | D13: 0.317 | E13: 0.325 | F13: 0.339 | G13: 0.349 | H13: 0.359 | I13: 0.367 | J13: 0.38 | K13: 0.391 | L13: 0.4 | M13: 0.407 | N13: 0.412 | O13: 0.418 | P13: 0.432 | Q13: 0.438 | R13: 0.445 | S13: 0.448 | T13: 0.45 | U13: 0.458 | V13: 0.465 | W13: 0.467 | X13: 0.459 | Y13: 0.461 | Z13: Africa | AA13: Emerging and Developing | AB13: 37 | AD13: 92 | AF13: Australia | AG13: =COUNTIFS($Z$2:$Z$176, AF13, $AA$2:$AA$176, "Advanced") -> 1 | AM13: HYPGEOMDIST – P(X=k) for each continent
A14: CAF | B14: Central African Republic | C14: 0.319 | D14: 0.321 | E14: 0.322 | F14: 0.322 | G14: 0.326 | H14: 0.33 | I14: 0.333 | J14: 0.339 | K14: 0.345 | L14: 0.35 | M14: 0.357 | N14: 0.365 | O14: 0.372 | P14: 0.352 | Q14: 0.354 | R14: 0.367 | S14: 0.373 | T14: 0.379 | U14: 0.386 | V14: 0.391 | W14: 0.389 | X14: 0.387 | Y14: 0.387 | Z14: Africa | AA14: Emerging and Developing | AB14: 38 | AD14: 158 | AF14: Europe | AG14: =COUNTIFS($Z$2:$Z$176, AF14, $AA$2:$AA$176, "Advanced") -> 24 | AM14: k | AN14: Africa | AO14: Asia | AP14: Australia | AQ14: Europe | AR14: N.America | AS14: Oceania | AT14: S.America | AU14: Conv:EUR+ASI | AV14: Conv:+AUS | AW14: Conv:+NAM | AX14: Conv:+OC | AY14: Conv:+SAM
A15: KEN | B15: Kenya | C15: 0.487 | D15: 0.49 | E15: 0.49 | F15: 0.501 | G15: 0.513 | H15: 0.521 | I15: 0.531 | J15: 0.54 | K15: 0.546 | L15: 0.546 | M15: 0.545 | N15: 0.552 | O15: 0.557 | P15: 0.562 | Q15: 0.569 | R15: 0.575 | S15: 0.586 | T15: 0.591 | U15: 0.598 | V15: 0.604 | W15: 0.599 | X15: 0.596 | Y15: 0.601 | Z15: Africa | AA15: Emerging and Developing | AB15: 45 | AD15: 17 | AF15: North America | AG15: =COUNTIFS($Z$2:$Z$176, AF15, $AA$2:$AA$176, "Advanced") -> 2 | AM15: 0 | AN15: =IF(0=0,1,0) -> 1 | AO15: =IF(0<=MIN(AP5,AO5),_xlfn.HYPGEOM.DIST(0,AP5,AO5,AN5,0),0) -> 0.00011049642 | AP15: =0 -> 0 | AQ15: =IF(0<=MIN(AP7,AO7),_xlfn.HYPGEOM.DIST(0,AP7,AO7,AN7,0),0) -> 0 | AR15: =IF(0<=MIN(AP8,AO8),_xlfn.HYPGEOM.DIST(0,AP8,AO8,AN8,0),0) -> 0.014285714 | AS15: =IF(0<=MIN(AP9,AO9),_xlfn.HYPGEOM.DIST(0,AP9,AO9,AN9,0),0) -> 0.1 | AT15: =IF(0=0,1,0) -> 1 | AU15: =AQ15*AO15 -> 0 | AV15: =IF(0>=1,AU14,0) -> 0 | AW15: =AV15*AR15 -> 0 | AX15: =AW15*AS15 -> 0 | AY15: =AX15 -> 0
A16: COM | B16: Comoros | C16: 0.458 | D16: 0.466 | E16: 0.472 | F16: 0.478 | G16: 0.484 | H16: 0.491 | I16: 0.497 | J16: 0.503 | K16: 0.51 | L16: 0.517 | M16: 0.524 | N16: 0.532 | O16: 0.538 | P16: 0.546 | Q16: 0.551 | R16: 0.556 | S16: 0.563 | T16: 0.571 | U16: 0.578 | V16: 0.584 | W16: 0.588 | X16: 0.585 | Y16: 0.586 | Z16: Africa | AA16: Emerging and Developing | AB16: 47 | AD16: 122 | AF16: Oceania | AG16: =COUNTIFS($Z$2:$Z$176, AF16, $AA$2:$AA$176, "Advanced") -> 1 | AM16: 1 | AN16: =0 -> 0 | AO16: =IF(1<=MIN(AP5,AO5),_xlfn.HYPGEOM.DIST(1,AP5,AO5,AN5,0),0) -> 0.0055984855 | AP16: =IF(1=1,1,0) -> 1 | AQ16: =IF(1<=MIN(AP7,AO7),_xlfn.HYPGEOM.DIST(1,AP7,AO7,AN7,0),0) -> 0 | AR16: =IF(1<=MIN(AP8,AO8),_xlfn.HYPGEOM.DIST(1,AP8,AO8,AN8,0),0) -> 0.25714286 | AS16: =IF(1<=MIN(AP9,AO9),_xlfn.HYPGEOM.DIST(1,AP9,AO9,AN9,0),0) -> 0.9 | AT16: =0 -> 0 | AU16: =AQ15*AO16+AQ16*AO15 -> 0 | AV16: =IF(1>=1,AU15,0) -> 0 | AW16: =AV15*AR16+AV16*AR15 -> 0 | AX16: =AW15*AS16+AW16*AS15 -> 0 | AY16: =AX16 -> 0
A17: STP | B17: Sao Tome and Principe | C17: 0.498 | D17: 0.504 | E17: 0.508 | F17: 0.516 | G17: 0.522 | H17: 0.529 | I17: 0.539 | J17: 0.543 | K17: 0.544 | L17: 0.55 | M17: 0.553 | N17: 0.556 | O17: 0.562 | P17: 0.573 | Q17: 0.584 | R17: 0.595 | S17: 0.599 | T17: 0.604 | U17: 0.607 | V17: 0.608 | W17: 0.609 | X17: 0.609 | Y17: 0.613 | Z17: Africa | AA17: Emerging and Developing | AB17: 48 | AD17: 54 | AF17: South America | AG17: =COUNTIFS($Z$2:$Z$176, AF17, $AA$2:$AA$176, "Advanced") -> 0 | AM17: 2 | AN17: =0 -> 0 | AO17: =IF(2<=MIN(AP5,AO5),_xlfn.HYPGEOM.DIST(2,AP5,AO5,AN5,0),0) -> 0.077678986 | AP17: =0 -> 0 | AQ17: =IF(2<=MIN(AP7,AO7),_xlfn.HYPGEOM.DIST(2,AP7,AO7,AN7,0),0) -> 0 | AR17: =IF(2<=MIN(AP8,AO8),_xlfn.HYPGEOM.DIST(2,AP8,AO8,AN8,0),0) -> 0.72857143 | AS17: =IF(2<=MIN(AP9,AO9),_xlfn.HYPGEOM.DIST(2,AP9,AO9,AN9,0),0) -> 0 | AT17: =0 -> 0 | AU17: =AQ15*AO17+AQ16*AO16+AQ17*AO15 -> 0 | AV17: =IF(2>=1,AU16,0) -> 0 | AW17: =AV15*AR17+AV16*AR16+AV17*AR15 -> 0 | AX17: =AW15*AS17+AW16*AS16+AW17*AS15 -> 0 | AY17: =AX17 -> 0
A18: GMB | B18: Gambia | C18: 0.392 | D18: 0.398 | E18: 0.402 | F18: 0.408 | G18: 0.419 | H18: 0.422 | I18: 0.427 | J18: 0.433 | K18: 0.442 | L18: 0.446 | M18: 0.449 | N18: 0.45 | O18: 0.457 | P18: 0.461 | Q18: 0.462 | R18: 0.467 | S18: 0.472 | T18: 0.477 | U18: 0.483 | V18: 0.492 | W18: 0.492 | X18: 0.49 | Y18: 0.495 | Z18: Africa | AA18: Emerging and Developing | AB18: 54 | AD18: 73 | AG18: =SUM(AG11:AG17) -> 32 | AM18: 3 | AN18: =0 -> 0 | AO18: =IF(3<=MIN(AP5,AO5),_xlfn.HYPGEOM.DIST(3,AP5,AO5,AN5,0),0) -> 0.37285913 | AP18: =0 -> 0 | AQ18: =IF(3<=MIN(AP7,AO7),_xlfn.HYPGEOM.DIST(3,AP7,AO7,AN7,0),0) -> 0 | AR18: =IF(3<=MIN(AP8,AO8),_xlfn.HYPGEOM.DIST(3,AP8,AO8,AN8,0),0) -> 0 | AS18: =IF(3<=MIN(AP9,AO9),_xlfn.HYPGEOM.DIST(3,AP9,AO9,AN9,0),0) -> 0 | AT18: =0 -> 0 | AU18: =AQ15*AO18+AQ16*AO17+AQ17*AO16+AQ18*AO15 -> 0 | AV18: =IF(3>=1,AU17,0) -> 0 | AW18: =AV15*AR18+AV16*AR17+AV17*AR16+AV18*AR15 -> 0 | AX18: =AW15*AS18+AW16*AS17+AW17*AS16+AW18*AS15 -> 0 | AY18: =AX18 -> 0
A19: DJI | B19: Djibouti | C19: 0.33 | D19: 0.34 | E19: 0.346 | F19: 0.357 | G19: 0.365 | H19: 0.374 | I19: 0.384 | J19: 0.394 | K19: 0.401 | L19: 0.411 | M19: 0.422 | N19: 0.432 | O19: 0.444 | P19: 0.453 | Q19: 0.463 | R19: 0.473 | S19: 0.482 | T19: 0.491 | U19: 0.499 | V19: 0.508 | W19: 0.512 | X19: 0.512 | Y19: 0.515 | Z19: Africa | AA19: Emerging and Developing | AB19: 61 | AD19: 134 | AM19: 4 | AN19: =0 -> 0 | AO19: =IF(4<=MIN(AP5,AO5),_xlfn.HYPGEOM.DIST(4,AP5,AO5,AN5,0),0) -> 0.5437529 | AP19: =0 -> 0 | AQ19: =IF(4<=MIN(AP7,AO7),_xlfn.HYPGEOM.DIST(4,AP7,AO7,AN7,0),0) -> 0 | AR19: =IF(4<=MIN(AP8,AO8),_xlfn.HYPGEOM.DIST(4,AP8,AO8,AN8,0),0) -> 0 | AS19: =IF(4<=MIN(AP9,AO9),_xlfn.HYPGEOM.DIST(4,AP9,AO9,AN9,0),0) -> 0 | AT19: =0 -> 0 | AU19: =AQ15*AO19+AQ16*AO18+AQ17*AO17+AQ18*AO16+AQ19*AO15 -> 0 | AV19: =IF(4>=1,AU18,0) -> 0 | AW19: =AV15*AR19+AV16*AR18+AV17*AR17+AV18*AR16+AV19*AR15 -> 0 | AX19: =AW15*AS19+AW16*AS18+AW17*AS17+AW18*AS16+AW19*AS15 -> 0 | AY19: =AX19 -> 0
A20: DZA | B20: Algeria | C20: 0.652 | D20: 0.659 | E20: 0.668 | F20: 0.675 | G20: 0.683 | H20: 0.69 | I20: 0.696 | J20: 0.701 | K20: 0.709 | L20: 0.716 | M20: 0.721 | N20: 0.725 | O20: 0.726 | P20: 0.729 | Q20: 0.732 | R20: 0.736 | S20: 0.738 | T20: 0.738 | U20: 0.74 | V20: 0.742 | W20: 0.73 | X20: 0.74 | Y20: 0.745 | Z20: Africa | AA20: Emerging and Developing | AB20: 63 | AD20: 27 | AF20: Advanced in sample | AG20: =COUNTIF(AA2:AA42,"Advanced") + COUNTIF(AA50:AA87, "Advanced") + COUNTIF(AA94, "Advanced") + COUNTIF(AA95:AA128, "Advanced") + COUNTIF(AA135:AA152, "Advanced") + COUNTIF(AA156:AA164, "Advanced") + COUNTIF(AA166:AA175, "Advanced") -> 30 | AM20: 5 | AN20: =0 -> 0 | AO20: =IF(5<=MIN(AP5,AO5),_xlfn.HYPGEOM.DIST(5,AP5,AO5,AN5,0),0) -> 0 | AP20: =0 -> 0 | AQ20: =IF(5<=MIN(AP7,AO7),_xlfn.HYPGEOM.DIST(5,AP7,AO7,AN7,0),0) -> 0 | AR20: =IF(5<=MIN(AP8,AO8),_xlfn.HYPGEOM.DIST(5,AP8,AO8,AN8,0),0) -> 0 | AS20: =IF(5<=MIN(AP9,AO9),_xlfn.HYPGEOM.DIST(5,AP9,AO9,AN9,0),0) -> 0 | AT20: =0 -> 0 | AU20: =AQ15*AO20+AQ16*AO19+AQ17*AO18+AQ18*AO17+AQ19*AO16+AQ20*AO15 -> 0 | AV20: =IF(5>=1,AU19,0) -> 0 | AW20: =AV15*AR20+AV16*AR19+AV17*AR18+AV18*AR17+AV19*AR16+AV20*AR15 -> 0 | AX20: =AW15*AS20+AW16*AS19+AW17*AS18+AW18*AS17+AW19*AS16+AW20*AS15 -> 0 | AY20: =AX20 -> 0
A21: TZA | B21: Tanzania (United Republic of) | C21: 0.396 | D21: 0.404 | E21: 0.414 | F21: 0.425 | G21: 0.435 | H21: 0.445 | I21: 0.455 | J21: 0.464 | K21: 0.472 | L21: 0.482 | M21: 0.493 | N21: 0.498 | O21: 0.501 | P21: 0.504 | Q21: 0.506 | R21: 0.507 | S21: 0.509 | T21: 0.517 | U21: 0.525 | V21: 0.533 | W21: 0.535 | X21: 0.529 | Y21: 0.532 | Z21: Africa | AA21: Emerging and Developing | AB21: 66 | AD21: 11 | AM21: 6 | AN21: =0 -> 0 | AO21: =IF(6<=MIN(AP5,AO5),_xlfn.HYPGEOM.DIST(6,AP5,AO5,AN5,0),0) -> 0 | AP21: =0 -> 0 | AQ21: =IF(6<=MIN(AP7,AO7),_xlfn.HYPGEOM.DIST(6,AP7,AO7,AN7,0),0) -> 0 | AR21: =IF(6<=MIN(AP8,AO8),_xlfn.HYPGEOM.DIST(6,AP8,AO8,AN8,0),0) -> 0 | AS21: =IF(6<=MIN(AP9,AO9),_xlfn.HYPGEOM.DIST(6,AP9,AO9,AN9,0),0) -> 0 | AT21: =0 -> 0 | AU21: =AQ15*AO21+AQ16*AO20+AQ17*AO19+AQ18*AO18+AQ19*AO17+AQ20*AO16+AQ21*AO15 -> 0 | AV21: =IF(6>=1,AU20,0) -> 0 | AW21: =AV15*AR21+AV16*AR20+AV17*AR19+AV18*AR18+AV19*AR17+AV20*AR16+AV21*AR15 -> 0 | AX21: =AW15*AS21+AW16*AS20+AW17*AS19+AW18*AS18+AW19*AS17+AW20*AS16+AW21*AS15 -> 0 | AY21: =AX21 -> 0
A22: COG | B22: Congo | C22: 0.509 | D22: 0.515 | E22: 0.518 | F22: 0.52 | G22: 0.525 | H22: 0.539 | I22: 0.552 | J22: 0.553 | K22: 0.561 | L22: 0.574 | M22: 0.581 | N22: 0.584 | O22: 0.595 | P22: 0.6 | Q22: 0.609 | R22: 0.61 | S22: 0.606 | T22: 0.6 | U22: 0.603 | V22: 0.596 | W22: 0.598 | X22: 0.598 | Y22: 0.593 | Z22: Africa | AA22: Emerging and Developing | AB22: 78 | AD22: 16 | AM22: 7 | AN22: =0 -> 0 | AO22: =IF(7<=MIN(AP5,AO5),_xlfn.HYPGEOM.DIST(7,AP5,AO5,AN5,0),0) -> 0 | AP22: =0 -> 0 | AQ22: =IF(7<=MIN(AP7,AO7),_xlfn.HYPGEOM.DIST(7,AP7,AO7,AN7,0),0) -> 0 | AR22: =IF(7<=MIN(AP8,AO8),_xlfn.HYPGEOM.DIST(7,AP8,AO8,AN8,0),0) -> 0 | AS22: =IF(7<=MIN(AP9,AO9),_xlfn.HYPGEOM.DIST(7,AP9,AO9,AN9,0),0) -> 0 | AT22: =0 -> 0 | AU22: =AQ15*AO22+AQ16*AO21+AQ17*AO20+AQ18*AO19+AQ19*AO18+AQ20*AO17+AQ21*AO16+AQ22*AO15 -> 0 | AV22: =IF(7>=1,AU21,0) -> 0 | AW22: =AV15*AR22+AV16*AR21+AV17*AR20+AV18*AR19+AV19*AR18+AV20*AR17+AV21*AR16+AV22*AR15 -> 0 | AX22: =AW15*AS22+AW16*AS21+AW17*AS20+AW18*AS19+AW19*AS18+AW20*AS17+AW21*AS16+AW22*AS15 -> 0 | AY22: =AX22 -> 0
A23: MDG | B23: Madagascar | C23: 0.438 | D23: 0.445 | E23: 0.442 | F23: 0.451 | G23: 0.459 | H23: 0.464 | I23: 0.469 | J23: 0.477 | K23: 0.485 | L23: 0.488 | M23: 0.488 | N23: 0.49 | O23: 0.492 | P23: 0.494 | Q23: 0.497 | R23: 0.499 | S23: 0.501 | T23: 0.502 | U23: 0.502 | V23: 0.498 | W23: 0.486 | X23: 0.484 | Y23: 0.487 | Z23: Africa | AA23: Emerging and Developing | AB23: 79 | AD23: 123 | AM23: 8 | AN23: =0 -> 0 | AO23: =IF(8<=MIN(AP5,AO5),_xlfn.HYPGEOM.DIST(8,AP5,AO5,AN5,0),0) -> 0 | AP23: =0 -> 0 | AQ23: =IF(8<=MIN(AP7,AO7),_xlfn.HYPGEOM.DIST(8,AP7,AO7,AN7,0),0) -> 0 | AR23: =IF(8<=MIN(AP8,AO8),_xlfn.HYPGEOM.DIST(8,AP8,AO8,AN8,0),0) -> 0 | AS23: =IF(8<=MIN(AP9,AO9),_xlfn.HYPGEOM.DIST(8,AP9,AO9,AN9,0),0) -> 0 | AT23: =0 -> 0 | AU23: =AQ15*AO23+AQ16*AO22+AQ17*AO21+AQ18*AO20+AQ19*AO19+AQ20*AO18+AQ21*AO17+AQ22*AO16+AQ23*AO15 -> 0 | AV23: =IF(8>=1,AU22,0) -> 0 | AW23: =AV15*AR23+AV16*AR22+AV17*AR21+AV18*AR20+AV19*AR19+AV20*AR18+AV21*AR17+AV22*AR16+AV23*AR15 -> 0 | AX23: =AW15*AS23+AW16*AS22+AW17*AS21+AW18*AS20+AW19*AS19+AW20*AS18+AW21*AS17+AW22*AS16+AW23*AS15 -> 0 | AY23: =AX23 -> 0
A24: GIN | B24: Guinea | C24: 0.345 | D24: 0.352 | E24: 0.363 | F24: 0.37 | G24: 0.377 | H24: 0.387 | I24: 0.394 | J24: 0.402 | K24: 0.408 | L24: 0.41 | M24: 0.415 | N24: 0.421 | O24: 0.425 | P24: 0.43 | Q24: 0.436 | R24: 0.449 | S24: 0.466 | T24: 0.467 | U24: 0.464 | V24: 0.47 | W24: 0.471 | X24: 0.467 | Y24: 0.471 | Z24: Africa | AA24: Emerging and Developing | AB24: 81 | AD24: 28 | AM24: 9 | AN24: =0 -> 0 | AO24: =IF(9<=MIN(AP5,AO5),_xlfn.HYPGEOM.DIST(9,AP5,AO5,AN5,0),0) -> 0 | AP24: =0 -> 0 | AQ24: =IF(9<=MIN(AP7,AO7),_xlfn.HYPGEOM.DIST(9,AP7,AO7,AN7,0),0) -> 0 | AR24: =IF(9<=MIN(AP8,AO8),_xlfn.HYPGEOM.DIST(9,AP8,AO8,AN8,0),0) -> 0 | AS24: =IF(9<=MIN(AP9,AO9),_xlfn.HYPGEOM.DIST(9,AP9,AO9,AN9,0),0) -> 0 | AT24: =0 -> 0 | AU24: =AQ15*AO24+AQ16*AO23+AQ17*AO22+AQ18*AO21+AQ19*AO20+AQ20*AO19+AQ21*AO18+AQ22*AO17+AQ23*AO16+AQ24*AO15 -> 0 | AV24: =IF(9>=1,AU23,0) -> 0 | AW24: =AV15*AR24+AV16*AR23+AV17*AR22+AV18*AR21+AV19*AR20+AV20*AR19+AV21*AR18+AV22*AR17+AV23*AR16+AV24*AR15 -> 0 | AX24: =AW15*AS24+AW16*AS23+AW17*AS22+AW18*AS21+AW19*AS20+AW20*AS19+AW21*AS18+AW22*AS17+AW23*AS16+AW24*AS15 -> 0 | AY24: =AX24 -> 0
A25: CMR | B25: Cameroon | C25: 0.426 | D25: 0.445 | E25: 0.445 | F25: 0.452 | G25: 0.458 | H25: 0.459 | I25: 0.46 | J25: 0.472 | K25: 0.487 | L25: 0.502 | M25: 0.515 | N25: 0.524 | O25: 0.535 | P25: 0.544 | Q25: 0.553 | R25: 0.562 | S25: 0.566 | T25: 0.574 | U25: 0.581 | V25: 0.586 | W25: 0.585 | X25: 0.581 | Y25: 0.587 | Z25: Africa | AA25: Emerging and Developing | AB25: 89 | AD25: 62 | AM25: 10 | AN25: =0 -> 0 | AO25: =IF(10<=MIN(AP5,AO5),_xlfn.HYPGEOM.DIST(10,AP5,AO5,AN5,0),0) -> 0 | AP25: =0 -> 0 | AQ25: =IF(10<=MIN(AP7,AO7),_xlfn.HYPGEOM.DIST(10,AP7,AO7,AN7,0),0) -> 0 | AR25: =IF(10<=MIN(AP8,AO8),_xlfn.HYPGEOM.DIST(10,AP8,AO8,AN8,0),0) -> 0 | AS25: =IF(10<=MIN(AP9,AO9),_xlfn.HYPGEOM.DIST(10,AP9,AO9,AN9,0),0) -> 0 | AT25: =0 -> 0 | AU25: =AQ15*AO25+AQ16*AO24+AQ17*AO23+AQ18*AO22+AQ19*AO21+AQ20*AO20+AQ21*AO19+AQ22*AO18+AQ23*AO17+AQ24*AO16+AQ25*AO15 -> 0 | AV25: =IF(10>=1,AU24,0) -> 0 | AW25: =AV15*AR25+AV16*AR24+AV17*AR23+AV18*AR22+AV19*AR21+AV20*AR20+AV21*AR19+AV22*AR18+AV23*AR17+AV24*AR16+AV25*AR15 -> 0 | AX25: =AW15*AS25+AW16*AS24+AW17*AS23+AW18*AS22+AW19*AS21+AW20*AS20+AW21*AS19+AW22*AS18+AW23*AS17+AW24*AS16+AW25*AS15 -> 0 | AY25: =AX25 -> 0
A26: LBR | B26: Liberia | C26: 0.434 | D26: 0.44 | E26: 0.446 | F26: 0.422 | G26: 0.435 | H26: 0.439 | I26: 0.443 | J26: 0.448 | K26: 0.453 | L26: 0.456 | M26: 0.46 | N26: 0.464 | O26: 0.469 | P26: 0.474 | Q26: 0.472 | R26: 0.472 | S26: 0.478 | T26: 0.481 | U26: 0.484 | V26: 0.485 | W26: 0.483 | X26: 0.484 | Y26: 0.487 | Z26: Africa | AA26: Emerging and Developing | AB26: 93 | AD26: 98 | AM26: 11 | AN26: =0 -> 0 | AO26: =IF(11<=MIN(AP5,AO5),_xlfn.HYPGEOM.DIST(11,AP5,AO5,AN5,0),0) -> 0 | AP26: =0 -> 0 | AQ26: =IF(11<=MIN(AP7,AO7),_xlfn.HYPGEOM.DIST(11,AP7,AO7,AN7,0),0) -> 0 | AR26: =IF(11<=MIN(AP8,AO8),_xlfn.HYPGEOM.DIST(11,AP8,AO8,AN8,0),0) -> 0 | AS26: =IF(11<=MIN(AP9,AO9),_xlfn.HYPGEOM.DIST(11,AP9,AO9,AN9,0),0) -> 0 | AT26: =0 -> 0 | AU26: =AQ15*AO26+AQ16*AO25+AQ17*AO24+AQ18*AO23+AQ19*AO22+AQ20*AO21+AQ21*AO20+AQ22*AO19+AQ23*AO18+AQ24*AO17+AQ25*AO16+AQ26*AO15 -> 0 | AV26: =IF(11>=1,AU25,0) -> 0 | AW26: =AV15*AR26+AV16*AR25+AV17*AR24+AV18*AR23+AV19*AR22+AV20*AR21+AV21*AR20+AV22*AR19+AV23*AR18+AV24*AR17+AV25*AR16+AV26*AR15 -> 0 | AX26: =AW15*AS26+AW16*AS25+AW17*AS24+AW18*AS23+AW19*AS22+AW20*AS21+AW21*AS20+AW22*AS19+AW23*AS18+AW24*AS17+AW25*AS16+AW26*AS15 -> 0 | AY26: =AX26 -> 0
A27: COD | B27: Congo (Democratic Republic of the) | C27: 0.376 | D27: 0.373 | E27: 0.376 | F27: 0.382 | G27: 0.388 | H27: 0.392 | I27: 0.397 | J27: 0.401 | K27: 0.41 | L27: 0.416 | M27: 0.424 | N27: 0.432 | O27: 0.434 | P27: 0.44 | Q27: 0.45 | R27: 0.457 | S27: 0.466 | T27: 0.469 | U27: 0.474 | V27: 0.476 | W27: 0.477 | X27: 0.475 | Y27: 0.481 | Z27: Africa | AA27: Emerging and Developing | AB27: 94 | AD27: 81 | AM27: 12 | AN27: =0 -> 0 | AO27: =IF(12<=MIN(AP5,AO5),_xlfn.HYPGEOM.DIST(12,AP5,AO5,AN5,0),0) -> 0 | AP27: =0 -> 0 | AQ27: =IF(12<=MIN(AP7,AO7),_xlfn.HYPGEOM.DIST(12,AP7,AO7,AN7,0),0) -> 0 | AR27: =IF(12<=MIN(AP8,AO8),_xlfn.HYPGEOM.DIST(12,AP8,AO8,AN8,0),0) -> 0 | AS27: =IF(12<=MIN(AP9,AO9),_xlfn.HYPGEOM.DIST(12,AP9,AO9,AN9,0),0) -> 0 | AT27: =0 -> 0 | AU27: =AQ15*AO27+AQ16*AO26+AQ17*AO25+AQ18*AO24+AQ19*AO23+AQ20*AO22+AQ21*AO21+AQ22*AO20+AQ23*AO19+AQ24*AO18+AQ25*AO17+AQ26*AO16+AQ27*AO15 -> 0 | AV27: =IF(12>=1,AU26,0) -> 0 | AW27: =AV15*AR27+AV16*AR26+AV17*AR25+AV18*AR24+AV19*AR23+AV20*AR22+AV21*AR21+AV22*AR20+AV23*AR19+AV24*AR18+AV25*AR17+AV26*AR16+AV27*AR15 -> 0 | AX27: =AW15*AS27+AW16*AS26+AW17*AS25+AW18*AS24+AW19*AS23+AW20*AS22+AW21*AS21+AW22*AS20+AW23*AS19+AW24*AS18+AW25*AS17+AW26*AS16+AW27*AS15 -> 0 | AY27: =AX27 -> 0
A28: BEN | B28: Benin | C28: 0.412 | D28: 0.423 | E28: 0.431 | F28: 0.438 | G28: 0.444 | H28: 0.45 | I28: 0.456 | J28: 0.464 | K28: 0.47 | L28: 0.475 | M28: 0.481 | N28: 0.486 | O28: 0.494 | P28: 0.503 | Q28: 0.506 | R28: 0.509 | S28: 0.508 | T28: 0.505 | U28: 0.506 | V28: 0.506 | W28: 0.501 | X28: 0.502 | Y28: 0.504 | Z28: Africa | AA28: Emerging and Developing | AB28: 96 | AD28: 154 | AM28: 13 | AN28: =0 -> 0 | AO28: =IF(13<=MIN(AP5,AO5),_xlfn.HYPGEOM.DIST(13,AP5,AO5,AN5,0),0) -> 0 | AP28: =0 -> 0 | AQ28: =IF(13<=MIN(AP7,AO7),_xlfn.HYPGEOM.DIST(13,AP7,AO7,AN7,0),0) -> 0 | AR28: =IF(13<=MIN(AP8,AO8),_xlfn.HYPGEOM.DIST(13,AP8,AO8,AN8,0),0) -> 0 | AS28: =IF(13<=MIN(AP9,AO9),_xlfn.HYPGEOM.DIST(13,AP9,AO9,AN9,0),0) -> 0 | AT28: =0 -> 0 | AU28: =AQ15*AO28+AQ16*AO27+AQ17*AO26+AQ18*AO25+AQ19*AO24+AQ20*AO23+AQ21*AO22+AQ22*AO21+AQ23*AO20+AQ24*AO19+AQ25*AO18+AQ26*AO17+AQ27*AO16+AQ28*AO15 -> 0 | AV28: =IF(13>=1,AU27,0) -> 0 | AW28: =AV15*AR28+AV16*AR27+AV17*AR26+AV18*AR25+AV19*AR24+AV20*AR23+AV21*AR22+AV22*AR21+AV23*AR20+AV24*AR19+AV25*AR18+AV26*AR17+AV27*AR16+AV28*AR15 -> 0 | AX28: =AW15*AS28+AW16*AS27+AW17*AS26+AW18*AS25+AW19*AS24+AW20*AS23+AW21*AS22+AW22*AS21+AW23*AS20+AW24*AS19+AW25*AS18+AW26*AS17+AW27*AS16+AW28*AS15 -> 0 | AY28: =AX28 -> 0
A29: RWA | B29: Rwanda | C29: 0.328 | D29: 0.346 | E29: 0.367 | F29: 0.385 | G29: 0.403 | H29: 0.421 | I29: 0.44 | J29: 0.454 | K29: 0.465 | L29: 0.477 | M29: 0.485 | N29: 0.493 | O29: 0.501 | P29: 0.502 | Q29: 0.507 | R29: 0.509 | S29: 0.518 | T29: 0.52 | U29: 0.522 | V29: 0.531 | W29: 0.535 | X29: 0.539 | Y29: 0.548 | Z29: Africa | AA29: Emerging and Developing | AB29: 99 | AD29: 132 | AM29: 14 | AN29: =0 -> 0 | AO29: =IF(14<=MIN(AP5,AO5),_xlfn.HYPGEOM.DIST(14,AP5,AO5,AN5,0),0) -> 0 | AP29: =0 -> 0 | AQ29: =IF(14<=MIN(AP7,AO7),_xlfn.HYPGEOM.DIST(14,AP7,AO7,AN7,0),0) -> 0 | AR29: =IF(14<=MIN(AP8,AO8),_xlfn.HYPGEOM.DIST(14,AP8,AO8,AN8,0),0) -> 0 | AS29: =IF(14<=MIN(AP9,AO9),_xlfn.HYPGEOM.DIST(14,AP9,AO9,AN9,0),0) -> 0 | AT29: =0 -> 0 | AU29: =AQ15*AO29+AQ16*AO28+AQ17*AO27+AQ18*AO26+AQ19*AO25+AQ20*AO24+AQ21*AO23+AQ22*AO22+AQ23*AO21+AQ24*AO20+AQ25*AO19+AQ26*AO18+AQ27*AO17+AQ28*AO16+AQ29*AO15 -> 0 | AV29: =IF(14>=1,AU28,0) -> 0 | AW29: =AV15*AR29+AV16*AR28+AV17*AR27+AV18*AR26+AV19*AR25+AV20*AR24+AV21*AR23+AV22*AR22+AV23*AR21+AV24*AR20+AV25*AR19+AV26*AR18+AV27*AR17+AV28*AR16+AV29*AR15 -> 0 | AX29: =AW15*AS29+AW16*AS28+AW17*AS27+AW18*AS26+AW19*AS25+AW20*AS24+AW21*AS23+AW22*AS22+AW23*AS21+AW24*AS20+AW25*AS19+AW26*AS18+AW27*AS17+AW28*AS16+AW29*AS15 -> 0 | AY29: =AX29 -> 0
A30: BFA | B30: Burkina Faso | C30: 0.296 | D30: 0.299 | E30: 0.302 | F30: 0.308 | G30: 0.317 | H30: 0.327 | I30: 0.335 | J30: 0.339 | K30: 0.352 | L30: 0.362 | M30: 0.372 | N30: 0.383 | O30: 0.393 | P30: 0.399 | Q30: 0.403 | R30: 0.413 | S30: 0.422 | T30: 0.432 | U30: 0.443 | V30: 0.446 | W30: 0.446 | X30: 0.445 | Y30: 0.438 | Z30: Africa | AA30: Emerging and Developing | AB30: 103 | AD30: 142 | AM30: 15 | AN30: =0 -> 0 | AO30: =IF(15<=MIN(AP5,AO5),_xlfn.HYPGEOM.DIST(15,AP5,AO5,AN5,0),0) -> 0 | AP30: =0 -> 0 | AQ30: =IF(15<=MIN(AP7,AO7),_xlfn.HYPGEOM.DIST(15,AP7,AO7,AN7,0),0) -> 0 | AR30: =IF(15<=MIN(AP8,AO8),_xlfn.HYPGEOM.DIST(15,AP8,AO8,AN8,0),0) -> 0 | AS30: =IF(15<=MIN(AP9,AO9),_xlfn.HYPGEOM.DIST(15,AP9,AO9,AN9,0),0) -> 0 | AT30: =0 -> 0 | AU30: =AQ15*AO30+AQ16*AO29+AQ17*AO28+AQ18*AO27+AQ19*AO26+AQ20*AO25+AQ21*AO24+AQ22*AO23+AQ23*AO22+AQ24*AO21+AQ25*AO20+AQ26*AO19+AQ27*AO18+AQ28*AO17+AQ29*AO16+AQ30*AO15 -> 0 | AV30: =IF(15>=1,AU29,0) -> 0 | AW30: =AV15*AR30+AV16*AR29+AV17*AR28+AV18*AR27+AV19*AR26+AV20*AR25+AV21*AR24+AV22*AR23+AV23*AR22+AV24*AR21+AV25*AR20+AV26*AR19+AV27*AR18+AV28*AR17+AV29*AR16+AV30*AR15 -> 0 | AX30: =AW15*AS30+AW16*AS29+AW17*AS28+AW18*AS27+AW19*AS26+AW20*AS25+AW21*AS24+AW22*AS23+AW23*AS22+AW24*AS21+AW25*AS20+AW26*AS19+AW27*AS18+AW28*AS17+AW29*AS16+AW30*AS15 -> 0 | AY30: =AX30 -> 0
A31: SWZ | B31: Eswatini (Kingdom of) | C31: 0.465 | D31: 0.456 | E31: 0.444 | F31: 0.438 | G31: 0.436 | H31: 0.439 | I31: 0.454 | J31: 0.464 | K31: 0.473 | L31: 0.481 | M31: 0.498 | N31: 0.514 | O31: 0.53 | P31: 0.546 | Q31: 0.56 | R31: 0.577 | S31: 0.59 | T31: 0.601 | U31: 0.613 | V31: 0.623 | W31: 0.622 | X31: 0.612 | Y31: 0.61 | Z31: Africa | AA31: Emerging and Developing | AB31: 105 | AD31: 39 | AM31: 16 | AN31: =0 -> 0 | AO31: =IF(16<=MIN(AP5,AO5),_xlfn.HYPGEOM.DIST(16,AP5,AO5,AN5,0),0) -> 0 | AP31: =0 -> 0 | AQ31: =IF(16<=MIN(AP7,AO7),_xlfn.HYPGEOM.DIST(16,AP7,AO7,AN7,0),0) -> 0 | AR31: =IF(16<=MIN(AP8,AO8),_xlfn.HYPGEOM.DIST(16,AP8,AO8,AN8,0),0) -> 0 | AS31: =IF(16<=MIN(AP9,AO9),_xlfn.HYPGEOM.DIST(16,AP9,AO9,AN9,0),0) -> 0 | AT31: =0 -> 0 | AU31: =AQ15*AO31+AQ16*AO30+AQ17*AO29+AQ18*AO28+AQ19*AO27+AQ20*AO26+AQ21*AO25+AQ22*AO24+AQ23*AO23+AQ24*AO22+AQ25*AO21+AQ26*AO20+AQ27*AO19+AQ28*AO18+AQ29*AO17+AQ30*AO16+AQ31*AO15 -> 0 | AV31: =IF(16>=1,AU30,0) -> 0 | AW31: =AV15*AR31+AV16*AR30+AV17*AR29+AV18*AR28+AV19*AR27+AV20*AR26+AV21*AR25+AV22*AR24+AV23*AR23+AV24*AR22+AV25*AR21+AV26*AR20+AV27*AR19+AV28*AR18+AV29*AR17+AV30*AR16+AV31*AR15 -> 0 | AX31: =AW15*AS31+AW16*AS30+AW17*AS29+AW18*AS28+AW19*AS27+AW20*AS26+AW21*AS25+AW22*AS24+AW23*AS23+AW24*AS22+AW25*AS21+AW26*AS20+AW27*AS19+AW28*AS18+AW29*AS17+AW30*AS16+AW31*AS15 -> 0 | AY31: =AX31 -> 0
A32: GAB | B32: Gabon | C32: 0.626 | D32: 0.632 | E32: 0.635 | F32: 0.638 | G32: 0.638 | H32: 0.643 | I32: 0.643 | J32: 0.646 | K32: 0.647 | L32: 0.652 | M32: 0.656 | N32: 0.661 | O32: 0.671 | P32: 0.678 | Q32: 0.687 | R32: 0.692 | S32: 0.696 | T32: 0.699 | U32: 0.699 | V32: 0.702 | W32: 0.704 | X32: 0.687 | Y32: 0.693 | Z32: Africa | AA32: Emerging and Developing | AB32: 106 | AD32: 85 | AM32: 17 | AN32: =0 -> 0 | AO32: =IF(17<=MIN(AP5,AO5),_xlfn.HYPGEOM.DIST(17,AP5,AO5,AN5,0),0) -> 0 | AP32: =0 -> 0 | AQ32: =IF(17<=MIN(AP7,AO7),_xlfn.HYPGEOM.DIST(17,AP7,AO7,AN7,0),0) -> 0 | AR32: =IF(17<=MIN(AP8,AO8),_xlfn.HYPGEOM.DIST(17,AP8,AO8,AN8,0),0) -> 0 | AS32: =IF(17<=MIN(AP9,AO9),_xlfn.HYPGEOM.DIST(17,AP9,AO9,AN9,0),0) -> 0 | AT32: =0 -> 0 | AU32: =AQ15*AO32+AQ16*AO31+AQ17*AO30+AQ18*AO29+AQ19*AO28+AQ20*AO27+AQ21*AO26+AQ22*AO25+AQ23*AO24+AQ24*AO23+AQ25*AO22+AQ26*AO21+AQ27*AO20+AQ28*AO19+AQ29*AO18+AQ30*AO17+AQ31*AO16+AQ32*AO15 -> 0 | AV32: =IF(17>=1,AU31,0) -> 0 | AW32: =AV15*AR32+AV16*AR31+AV17*AR30+AV18*AR29+AV19*AR28+AV20*AR27+AV21*AR26+AV22*AR25+AV23*AR24+AV24*AR23+AV25*AR22+AV26*AR21+AV27*AR20+AV28*AR19+AV29*AR18+AV30*AR17+AV31*AR16+AV32*AR15 -> 0 | AX32: =AW15*AS32+AW16*AS31+AW17*AS30+AW18*AS29+AW19*AS28+AW20*AS27+AW21*AS26+AW22*AS25+AW23*AS24+AW24*AS23+AW25*AS22+AW26*AS21+AW27*AS20+AW28*AS19+AW29*AS18+AW30*AS17+AW31*AS16+AW32*AS15 -> 0 | AY32: =AX32 -> 0
A33: ZAF | B33: South Africa | C33: 0.633 | D33: 0.629 | E33: 0.633 | F33: 0.629 | G33: 0.63 | H33: 0.632 | I33: 0.637 | J33: 0.644 | K33: 0.653 | L33: 0.665 | M33: 0.675 | N33: 0.686 | O33: 0.696 | P33: 0.705 | Q33: 0.714 | R33: 0.721 | S33: 0.711 | T33: 0.725 | U33: 0.731 | V33: 0.741 | W33: 0.722 | X33: 0.721 | Y33: 0.717 | Z33: Africa | AA33: Emerging and Developing | AB33: 109 | AD33: 112 | AM33: 18 | AN33: =0 -> 0 | AO33: =IF(18<=MIN(AP5,AO5),_xlfn.HYPGEOM.DIST(18,AP5,AO5,AN5,0),0) -> 0 | AP33: =0 -> 0 | AQ33: =IF(18<=MIN(AP7,AO7),_xlfn.HYPGEOM.DIST(18,AP7,AO7,AN7,0),0) -> 0.035065835 | AR33: =IF(18<=MIN(AP8,AO8),_xlfn.HYPGEOM.DIST(18,AP8,AO8,AN8,0),0) -> 0 | AS33: =IF(18<=MIN(AP9,AO9),_xlfn.HYPGEOM.DIST(18,AP9,AO9,AN9,0),0) -> 0 | AT33: =0 -> 0 | AU33: =AQ15*AO33+AQ16*AO32+AQ17*AO31+AQ18*AO30+AQ19*AO29+AQ20*AO28+AQ21*AO27+AQ22*AO26+AQ23*AO25+AQ24*AO24+AQ25*AO23+AQ26*AO22+AQ27*AO21+AQ28*AO20+AQ29*AO19+AQ30*AO18+AQ31*AO17+AQ32*AO16+AQ33*AO15 -> 3.8746494e-06 | AV33: =IF(18>=1,AU32,0) -> 0 | AW33: =AV15*AR33+AV16*AR32+AV17*AR31+AV18*AR30+AV19*AR29+AV20*AR28+AV21*AR27+AV22*AR26+AV23*AR25+AV24*AR24+AV25*AR23+AV26*AR22+AV27*AR21+AV28*AR20+AV29*AR19+AV30*AR18+AV31*AR17+AV32*AR16+AV33*AR15 -> 0 | AX33: =AW15*AS33+AW16*AS32+AW17*AS31+AW18*AS30+AW19*AS29+AW20*AS28+AW21*AS27+AW22*AS26+AW23*AS25+AW24*AS24+AW25*AS23+AW26*AS22+AW27*AS21+AW28*AS20+AW29*AS19+AW30*AS18+AW31*AS17+AW32*AS16+AW33*AS15 -> 0 | AY33: =AX33 -> 0
A34: CPV | B34: Cabo Verde | C34: 0.59 | D34: 0.598 | E34: 0.606 | F34: 0.612 | G34: 0.615 | H34: 0.622 | I34: 0.633 | J34: 0.639 | K34: 0.643 | L34: 0.645 | M34: 0.649 | N34: 0.657 | O34: 0.657 | P34: 0.664 | Q34: 0.663 | R34: 0.658 | S34: 0.664 | T34: 0.668 | U34: 0.664 | V34: 0.667 | W34: 0.649 | X34: 0.65 | Y34: 0.661 | Z34: Africa | AA34: Emerging and Developing | AB34: 115 | AD34: 130 | AM34: 19 | AN34: =0 -> 0 | AO34: =IF(19<=MIN(AP5,AO5),_xlfn.HYPGEOM.DIST(19,AP5,AO5,AN5,0),0) -> 0 | AP34: =0 -> 0 | AQ34: =IF(19<=MIN(AP7,AO7),_xlfn.HYPGEOM.DIST(19,AP7,AO7,AN7,0),0) -> 0.17717475 | AR34: =IF(19<=MIN(AP8,AO8),_xlfn.HYPGEOM.DIST(19,AP8,AO8,AN8,0),0) -> 0 | AS34: =IF(19<=MIN(AP9,AO9),_xlfn.HYPGEOM.DIST(19,AP9,AO9,AN9,0),0) -> 0 | AT34: =0 -> 0 | AU34: =AQ15*AO34+AQ16*AO33+AQ17*AO32+AQ18*AO31+AQ19*AO30+AQ20*AO29+AQ21*AO28+AQ22*AO27+AQ23*AO26+AQ24*AO25+AQ25*AO24+AQ26*AO23+AQ27*AO22+AQ28*AO21+AQ29*AO20+AQ30*AO19+AQ31*AO18+AQ32*AO17+AQ33*AO16+AQ34*AO15 -> 0.00021589274 | AV34: =IF(19>=1,AU33,0) -> 3.8746494e-06 | AW34: =AV15*AR34+AV16*AR33+AV17*AR32+AV18*AR31+AV19*AR30+AV20*AR29+AV21*AR28+AV22*AR27+AV23*AR26+AV24*AR25+AV25*AR24+AV26*AR23+AV27*AR22+AV28*AR21+AV29*AR20+AV30*AR19+AV31*AR18+AV32*AR17+AV33*AR16+AV34*AR15 -> 5.5352134e-08 | AX34: =AW15*AS34+AW16*AS33+AW17*AS32+AW18*AS31+AW19*AS30+AW20*AS29+AW21*AS28+AW22*AS27+AW23*AS26+AW24*AS25+AW25*AS24+AW26*AS23+AW27*AS22+AW28*AS21+AW29*AS20+AW30*AS19+AW31*AS18+AW32*AS17+AW33*AS16+AW34*AS15 -> 5.5352134e-09 | AY34: =AX34 -> 5.5352134e-09
A35: BWA | B35: Botswana | C35: 0.581 | D35: 0.581 | E35: 0.579 | F35: 0.585 | G35: 0.591 | H35: 0.601 | I35: 0.615 | J35: 0.629 | K35: 0.637 | L35: 0.639 | M35: 0.652 | N35: 0.66 | O35: 0.664 | P35: 0.676 | Q35: 0.683 | R35: 0.688 | S35: 0.697 | T35: 0.705 | U35: 0.7 | V35: 0.703 | W35: 0.701 | X35: 0.68 | Y35: 0.708 | Z35: Africa | AA35: Emerging and Developing | AB35: 128 | AD35: 100 | AM35: 20 | AN35: =0 -> 0 | AO35: =IF(20<=MIN(AP5,AO5),_xlfn.HYPGEOM.DIST(20,AP5,AO5,AN5,0),0) -> 0 | AP35: =0 -> 0 | AQ35: =IF(20<=MIN(AP7,AO7),_xlfn.HYPGEOM.DIST(20,AP7,AO7,AN7,0),0) -> 0.33220265 | AR35: =IF(20<=MIN(AP8,AO8),_xlfn.HYPGEOM.DIST(20,AP8,AO8,AN8,0),0) -> 0 | AS35: =IF(20<=MIN(AP9,AO9),_xlfn.HYPGEOM.DIST(20,AP9,AO9,AN9,0),0) -> 0 | AT35: =0 -> 0 | AU35: =AQ15*AO35+AQ16*AO34+AQ17*AO33+AQ18*AO32+AQ19*AO31+AQ20*AO30+AQ21*AO29+AQ22*AO28+AQ23*AO27+AQ24*AO26+AQ25*AO25+AQ26*AO24+AQ27*AO23+AQ28*AO22+AQ29*AO21+AQ30*AO20+AQ31*AO19+AQ32*AO18+AQ33*AO17+AQ34*AO16+AQ35*AO15 -> 0.0037524959 | AV35: =IF(20>=1,AU34,0) -> 0.00021589274 | AW35: =AV15*AR35+AV16*AR34+AV17*AR33+AV18*AR32+AV19*AR31+AV20*AR30+AV21*AR29+AV22*AR28+AV23*AR27+AV24*AR26+AV25*AR25+AV26*AR24+AV27*AR23+AV28*AR22+AV29*AR21+AV30*AR20+AV31*AR19+AV32*AR18+AV33*AR17+AV34*AR16+AV35*AR15 -> 4.0805205e-06 | AX35: =AW15*AS35+AW16*AS34+AW17*AS33+AW18*AS32+AW19*AS31+AW20*AS30+AW21*AS29+AW22*AS28+AW23*AS27+AW24*AS26+AW25*AS25+AW26*AS24+AW27*AS23+AW28*AS22+AW29*AS21+AW30*AS20+AW31*AS19+AW32*AS18+AW33*AS17+AW34*AS16+AW35*AS15 -> 4.5786897e-07 | AY35: =AX35 -> 4.5786897e-07
A36: MUS | B36: Mauritius | C36: 0.682 | D36: 0.692 | E36: 0.696 | F36: 0.704 | G36: 0.711 | H36: 0.719 | I36: 0.725 | J36: 0.732 | K36: 0.739 | L36: 0.746 | M36: 0.755 | N36: 0.764 | O36: 0.774 | P36: 0.779 | Q36: 0.788 | R36: 0.791 | S36: 0.794 | T36: 0.797 | U36: 0.8 | V36: 0.806 | W36: 0.792 | X36: 0.79 | Y36: 0.796 | Z36: Africa | AA36: Emerging and Developing | AB36: 131 | AD36: 6 | AM36: 21 | AN36: =0 -> 0 | AO36: =IF(21<=MIN(AP5,AO5),_xlfn.HYPGEOM.DIST(21,AP5,AO5,AN5,0),0) -> 0 | AP36: =0 -> 0 | AQ36: =IF(21<=MIN(AP7,AO7),_xlfn.HYPGEOM.DIST(21,AP7,AO7,AN7,0),0) -> 0.29529124 | AR36: =IF(21<=MIN(AP8,AO8),_xlfn.HYPGEOM.DIST(21,AP8,AO8,AN8,0),0) -> 0 | AS36: =IF(21<=MIN(AP9,AO9),_xlfn.HYPGEOM.DIST(21,AP9,AO9,AN9,0),0) -> 0 | AT36: =0 -> 0 | AU36: =AQ15*AO36+AQ16*AO35+AQ17*AO34+AQ18*AO33+AQ19*AO32+AQ20*AO31+AQ21*AO30+AQ22*AO29+AQ23*AO28+AQ24*AO27+AQ25*AO26+AQ26*AO25+AQ27*AO24+AQ28*AO23+AQ29*AO22+AQ30*AO21+AQ31*AO20+AQ32*AO19+AQ33*AO18+AQ34*AO17+AQ35*AO16+AQ36*AO15 -> 0.028729832 | AV36: =IF(21>=1,AU35,0) -> 0.0037524959 | AW36: =AV15*AR36+AV16*AR35+AV17*AR34+AV18*AR33+AV19*AR32+AV20*AR31+AV21*AR30+AV22*AR29+AV23*AR28+AV24*AR27+AV25*AR26+AV26*AR25+AV27*AR24+AV28*AR23+AV29*AR22+AV30*AR21+AV31*AR20+AV32*AR19+AV33*AR18+AV34*AR17+AV35*AR16+AV36*AR15 -> 0.00011194532 | AX36: =AW15*AS36+AW16*AS35+AW17*AS34+AW18*AS33+AW19*AS32+AW20*AS31+AW21*AS30+AW22*AS29+AW23*AS28+AW24*AS27+AW25*AS26+AW26*AS25+AW27*AS24+AW28*AS23+AW29*AS22+AW30*AS21+AW31*AS20+AW32*AS19+AW33*AS18+AW34*AS17+AW35*AS16+AW36*AS15 -> 1.4867e-05 | AY36: =AX36 -> 1.4867e-05
A37: TUN | B37: Tunisia | C37: 0.651 | D37: 0.658 | E37: 0.663 | F37: 0.669 | G37: 0.679 | H37: 0.686 | I37: 0.693 | J37: 0.7 | K37: 0.705 | L37: 0.709 | M37: 0.713 | N37: 0.715 | O37: 0.716 | P37: 0.719 | Q37: 0.721 | R37: 0.724 | S37: 0.728 | T37: 0.732 | U37: 0.737 | V37: 0.74 | W37: 0.734 | X37: 0.729 | Y37: 0.732 | Z37: Africa | AA37: Emerging and Developing | AB37: 133 | AD37: 13 | AM37: 22 | AN37: =0 -> 0 | AO37: =IF(22<=MIN(AP5,AO5),_xlfn.HYPGEOM.DIST(22,AP5,AO5,AN5,0),0) -> 0 | AP37: =0 -> 0 | AQ37: =IF(22<=MIN(AP7,AO7),_xlfn.HYPGEOM.DIST(22,AP7,AO7,AN7,0),0) -> 0.13086771 | AR37: =IF(22<=MIN(AP8,AO8),_xlfn.HYPGEOM.DIST(22,AP8,AO8,AN8,0),0) -> 0 | AS37: =IF(22<=MIN(AP9,AO9),_xlfn.HYPGEOM.DIST(22,AP9,AO9,AN9,0),0) -> 0 | AT37: =0 -> 0 | AU37: =AQ15*AO37+AQ16*AO36+AQ17*AO35+AQ18*AO34+AQ19*AO33+AQ20*AO32+AQ21*AO31+AQ22*AO30+AQ23*AO29+AQ24*AO28+AQ25*AO27+AQ26*AO26+AQ27*AO25+AQ28*AO24+AQ29*AO23+AQ30*AO22+AQ31*AO21+AQ32*AO20+AQ33*AO19+AQ34*AO18+AQ35*AO17+AQ36*AO16+AQ37*AO15 -> 0.11260118 | AV37: =IF(22>=1,AU36,0) -> 0.028729832 | AW37: =AV15*AR37+AV16*AR36+AV17*AR35+AV18*AR34+AV19*AR33+AV20*AR32+AV21*AR31+AV22*AR30+AV23*AR29+AV24*AR28+AV25*AR27+AV26*AR26+AV27*AR25+AV28*AR24+AV29*AR23+AV30*AR22+AV31*AR21+AV32*AR20+AV33*AR19+AV34*AR18+AV35*AR17+AV36*AR16+AV37*AR15 -> 0.001532647 | AX37: =AW15*AS37+AW16*AS36+AW17*AS35+AW18*AS34+AW19*AS33+AW20*AS32+AW21*AS31+AW22*AS30+AW23*AS29+AW24*AS28+AW25*AS27+AW26*AS26+AW27*AS25+AW28*AS24+AW29*AS23+AW30*AS22+AW31*AS21+AW32*AS20+AW33*AS19+AW34*AS18+AW35*AS17+AW36*AS16+AW37*AS15 -> 0.00025401549 | AY37: =AX37 -> 0.00025401549
A38: ZMB | B38: Zambia | C38: 0.418 | D38: 0.426 | E38: 0.434 | F38: 0.448 | G38: 0.459 | H38: 0.472 | I38: 0.484 | J38: 0.495 | K38: 0.506 | L38: 0.519 | M38: 0.528 | N38: 0.534 | O38: 0.548 | P38: 0.554 | Q38: 0.557 | R38: 0.563 | S38: 0.564 | T38: 0.568 | U38: 0.571 | V38: 0.574 | W38: 0.569 | X38: 0.565 | Y38: 0.569 | Z38: Africa | AA38: Emerging and Developing | AB38: 136 | AD38: 82 | AM38: 23 | AN38: =0 -> 0 | AO38: =IF(23<=MIN(AP5,AO5),_xlfn.HYPGEOM.DIST(23,AP5,AO5,AN5,0),0) -> 0 | AP38: =0 -> 0 | AQ38: =IF(23<=MIN(AP7,AO7),_xlfn.HYPGEOM.DIST(23,AP7,AO7,AN7,0),0) -> 0.027311522 | AR38: =IF(23<=MIN(AP8,AO8),_xlfn.HYPGEOM.DIST(23,AP8,AO8,AN8,0),0) -> 0 | AS38: =IF(23<=MIN(AP9,AO9),_xlfn.HYPGEOM.DIST(23,AP9,AO9,AN9,0),0) -> 0 | AT38: =0 -> 0 | AU38: =AQ15*AO38+AQ16*AO37+AQ17*AO36+AQ18*AO35+AQ19*AO34+AQ20*AO33+AQ21*AO32+AQ22*AO31+AQ23*AO30+AQ24*AO29+AQ25*AO28+AQ26*AO27+AQ27*AO26+AQ28*AO25+AQ29*AO24+AQ30*AO23+AQ31*AO22+AQ32*AO21+AQ33*AO20+AQ34*AO19+AQ35*AO18+AQ36*AO17+AQ37*AO16+AQ38*AO15 -> 0.24387768 | AV38: =IF(23>=1,AU37,0) -> 0.11260118 | AW38: =AV15*AR38+AV16*AR37+AV17*AR36+AV18*AR35+AV19*AR34+AV20*AR33+AV21*AR32+AV22*AR31+AV23*AR30+AV24*AR29+AV25*AR28+AV26*AR27+AV27*AR26+AV28*AR25+AV29*AR24+AV30*AR23+AV31*AR22+AV32*AR21+AV33*AR20+AV34*AR19+AV35*AR18+AV36*AR17+AV37*AR16+AV38*AR15 -> 0.011730221 | AX38: =AW15*AS38+AW16*AS37+AW17*AS36+AW18*AS35+AW19*AS34+AW20*AS33+AW21*AS32+AW22*AS31+AW23*AS30+AW24*AS29+AW25*AS28+AW26*AS27+AW27*AS26+AW28*AS25+AW29*AS24+AW30*AS23+AW31*AS22+AW32*AS21+AW33*AS20+AW34*AS19+AW35*AS18+AW36*AS17+AW37*AS16+AW38*AS15 -> 0.0025524043 | AY38: =AX38 -> 0.0025524043
A39: SEN | B39: Senegal | C39: 0.388 | D39: 0.395 | E39: 0.399 | F39: 0.407 | G39: 0.414 | H39: 0.421 | I39: 0.429 | J39: 0.442 | K39: 0.454 | L39: 0.461 | M39: 0.47 | N39: 0.483 | O39: 0.491 | P39: 0.497 | Q39: 0.501 | R39: 0.501 | S39: 0.51 | T39: 0.511 | U39: 0.515 | V39: 0.514 | W39: 0.514 | X39: 0.512 | Y39: 0.517 | Z39: Africa | AA39: Emerging and Developing | AB39: 137 | AD39: 21 | AM39: 24 | AN39: =0 -> 0 | AO39: =IF(24<=MIN(AP5,AO5),_xlfn.HYPGEOM.DIST(24,AP5,AO5,AN5,0),0) -> 0 | AP39: =0 -> 0 | AQ39: =IF(24<=MIN(AP7,AO7),_xlfn.HYPGEOM.DIST(24,AP7,AO7,AN7,0),0) -> 0.0020862968 | AR39: =IF(24<=MIN(AP8,AO8),_xlfn.HYPGEOM.DIST(24,AP8,AO8,AN8,0),0) -> 0 | AS39: =IF(24<=MIN(AP9,AO9),_xlfn.HYPGEOM.DIST(24,AP9,AO9,AN9,0),0) -> 0 | AT39: =0 -> 0 | AU39: =AQ15*AO39+AQ16*AO38+AQ17*AO37+AQ18*AO36+AQ19*AO35+AQ20*AO34+AQ21*AO33+AQ22*AO32+AQ23*AO31+AQ24*AO30+AQ25*AO29+AQ26*AO28+AQ27*AO27+AQ28*AO26+AQ29*AO25+AQ30*AO24+AQ31*AO23+AQ32*AO22+AQ33*AO21+AQ34*AO20+AQ35*AO19+AQ36*AO18+AQ37*AO17+AQ38*AO16+AQ39*AO15 -> 0.30105699 | AV39: =IF(24>=1,AU38,0) -> 0.24387768 | AW39: =AV15*AR39+AV16*AR38+AV17*AR37+AV18*AR36+AV19*AR35+AV20*AR34+AV21*AR33+AV22*AR32+AV23*AR31+AV24*AR30+AV25*AR29+AV26*AR28+AV27*AR27+AV28*AR26+AV29*AR25+AV30*AR24+AV31*AR23+AV32*AR22+AV33*AR21+AV34*AR20+AV35*AR19+AV36*AR18+AV37*AR17+AV38*AR16+AV39*AR15 -> 0.053370291 | AX39: =AW15*AS39+AW16*AS38+AW17*AS37+AW18*AS36+AW19*AS35+AW20*AS34+AW21*AS33+AW22*AS32+AW23*AS31+AW24*AS30+AW25*AS29+AW26*AS28+AW27*AS27+AW28*AS26+AW29*AS25+AW30*AS24+AW31*AS23+AW32*AS22+AW33*AS21+AW34*AS20+AW35*AS19+AW36*AS18+AW37*AS17+AW38*AS16+AW39*AS15 -> 0.015894228 | AY39: =AX39 -> 0.015894228
A40: MWI | B40: Malawi | C40: 0.378 | D40: 0.386 | E40: 0.394 | F40: 0.402 | G40: 0.41 | H40: 0.417 | I40: 0.426 | J40: 0.433 | K40: 0.442 | L40: 0.452 | M40: 0.461 | N40: 0.469 | O40: 0.476 | P40: 0.484 | Q40: 0.493 | R40: 0.498 | S40: 0.501 | T40: 0.506 | U40: 0.509 | V40: 0.514 | W40: 0.512 | X40: 0.509 | Y40: 0.508 | Z40: Africa | AA40: Emerging and Developing | AB40: 147 | AD40: 43 | AM40: 25 | AN40: =0 -> 0 | AO40: =IF(25<=MIN(AP5,AO5),_xlfn.HYPGEOM.DIST(25,AP5,AO5,AN5,0),0) -> 0 | AP40: =0 -> 0 | AQ40: =IF(25<=MIN(AP7,AO7),_xlfn.HYPGEOM.DIST(25,AP7,AO7,AN7,0),0) -> 0 | AR40: =IF(25<=MIN(AP8,AO8),_xlfn.HYPGEOM.DIST(25,AP8,AO8,AN8,0),0) -> 0 | AS40: =IF(25<=MIN(AP9,AO9),_xlfn.HYPGEOM.DIST(25,AP9,AO9,AN9,0),0) -> 0 | AT40: =0 -> 0 | AU40: =AQ15*AO40+AQ16*AO39+AQ17*AO38+AQ18*AO37+AQ19*AO36+AQ20*AO35+AQ21*AO34+AQ22*AO33+AQ23*AO32+AQ24*AO31+AQ25*AO30+AQ26*AO29+AQ27*AO28+AQ28*AO27+AQ29*AO26+AQ30*AO25+AQ31*AO24+AQ32*AO23+AQ33*AO22+AQ34*AO21+AQ35*AO20+AQ36*AO19+AQ37*AO18+AQ38*AO17+AQ39*AO16+AQ40*AO15 -> 0.2114939 | AV40: =IF(25>=1,AU39,0) -> 0.30105699 | AW40: =AV15*AR40+AV16*AR39+AV17*AR38+AV18*AR37+AV19*AR36+AV20*AR35+AV21*AR34+AV22*AR33+AV23*AR32+AV24*AR31+AV25*AR30+AV26*AR29+AV27*AR28+AV28*AR27+AV29*AR26+AV30*AR25+AV31*AR24+AV32*AR23+AV33*AR22+AV34*AR21+AV35*AR20+AV36*AR19+AV37*AR18+AV38*AR17+AV39*AR16+AV40*AR15 -> 0.14905022 | AX40: =AW15*AS40+AW16*AS39+AW17*AS38+AW18*AS37+AW19*AS36+AW20*AS35+AW21*AS34+AW22*AS33+AW23*AS32+AW24*AS31+AW25*AS30+AW26*AS29+AW27*AS28+AW28*AS27+AW29*AS26+AW30*AS25+AW31*AS24+AW32*AS23+AW33*AS22+AW34*AS21+AW35*AS20+AW36*AS19+AW37*AS18+AW38*AS17+AW39*AS16+AW40*AS15 -> 0.062938283 | AY40: =AX40 -> 0.062938283
...

Sheet Sheet2
A1: iso3 | B1: country | C1: hdi_2000 | D1: hdi_2001 | E1: hdi_2002 | F1: hdi_2003 | G1: hdi_2004 | H1: hdi_2005 | I1: hdi_2006 | J1: hdi_2007 | K1: hdi_2008 | L1: hdi_2009 | M1: hdi_2010 | N1: hdi_2011 | O1: hdi_2012 | P1: hdi_2013 | Q1: hdi_2014 | R1: hdi_2015 | S1: hdi_2016 | T1: hdi_2017 | U1: hdi_2018 | V1: hdi_2019 | W1: hdi_2020 | X1: hdi_2021 | Y1: hdi_2022 | Z1: continents | AA1: economic_status | AB1: N_locked | AC1: log_gdp_per_capita_2022
A2: GNQ | B2: Equatorial Guinea | C2: 0.511 | D2: 0.524 | E2: 0.539 | F2: 0.545 | G2: 0.556 | H2: 0.57 | I2: 0.587 | J2: 0.599 | K2: 0.606 | L2: 0.613 | M2: 0.609 | N2: 0.618 | O2: 0.628 | P2: 0.633 | Q2: 0.639 | R2: 0.648 | S2: 0.65 | T2: 0.65 | U2: 0.652 | V2: 0.653 | W2: 0.65 | X2: 0.647 | Y2: 0.65 | Z2: Africa | AA2: Emerging and Developing | AB2: 4 | AC2: =LN(_xlfn.XLOOKUP(Sheet2!A2,DataSheet!$G$2:$G$267,DataSheet!$H$2:$H$267)) -> 8.9344946
A3: LBY | B3: Libya | C3: 0.746 | D3: 0.748 | E3: 0.75 | F3: 0.755 | G3: 0.758 | H3: 0.764 | I3: 0.768 | J3: 0.771 | K3: 0.773 | L3: 0.772 | M3: 0.774 | N3: 0.734 | O3: 0.777 | P3: 0.766 | Q3: 0.75 | R3: 0.749 | S3: 0.746 | T3: 0.761 | U3: 0.764 | V3: 0.756 | W3: 0.737 | X3: 0.746 | Y3: 0.746 | Z3: Africa | AA3: Emerging and Developing | AB3: 5 | AC3: =LN(_xlfn.XLOOKUP(Sheet2!A3,DataSheet!$G$2:$G$267,DataSheet!$H$2:$H$267)) -> 8.6972851
A4: TGO | B4: Togo | C4: 0.436 | D4: 0.439 | E4: 0.443 | F4: 0.449 | G4: 0.448 | H4: 0.446 | I4: 0.452 | J4: 0.445 | K4: 0.452 | L4: 0.46 | M4: 0.469 | N4: 0.483 | O4: 0.487 | P4: 0.495 | Q4: 0.502 | R4: 0.51 | S4: 0.515 | T4: 0.522 | U4: 0.528 | V4: 0.536 | W4: 0.54 | X4: 0.545 | Y4: 0.547 | Z4: Africa | AA4: Emerging and Developing | AB4: 6 | AC4: =LN(_xlfn.XLOOKUP(Sheet2!A4,DataSheet!$G$2:$G$267,DataSheet!$H$2:$H$267)) -> 6.8577584
A5: GHA | B5: Ghana | C5: 0.5 | D5: 0.499 | E5: 0.506 | F5: 0.51 | G5: 0.517 | H5: 0.529 | I5: 0.537 | J5: 0.547 | K5: 0.558 | L5: 0.563 | M5: 0.571 | N5: 0.579 | O5: 0.583 | P5: 0.587 | Q5: 0.582 | R5: 0.586 | S5: 0.586 | T5: 0.585 | U5: 0.589 | V5: 0.599 | W5: 0.601 | X5: 0.6 | Y5: 0.602 | Z5: Africa | AA5: Emerging and Developing | AB5: 14 | AC5: =LN(_xlfn.XLOOKUP(Sheet2!A5,DataSheet!$G$2:$G$267,DataSheet!$H$2:$H$267)) -> 7.7097081
A6: ETH | B6: Ethiopia | C6: 0.286 | D6: 0.299 | E6: 0.305 | F6: 0.31 | G6: 0.323 | H6: 0.343 | I6: 0.359 | J6: 0.376 | K6: 0.391 | L6: 0.399 | M6: 0.409 | N6: 0.419 | O6: 0.426 | P6: 0.437 | Q6: 0.445 | R6: 0.455 | S6: 0.465 | T6: 0.472 | U6: 0.479 | V6: 0.485 | W6: 0.489 | X6: 0.489 | Y6: 0.492 | Z6: Africa | AA6: Emerging and Developing | AB6: 17 | AC6: =LN(_xlfn.XLOOKUP(Sheet2!A6,DataSheet!$G$2:$G$267,DataSheet!$H$2:$H$267)) -> 6.8896964
A7: TCD | B7: Chad | C7: 0.292 | D7: 0.302 | E7: 0.309 | F7: 0.309 | G7: 0.327 | H7: 0.329 | I7: 0.328 | J7: 0.339 | K7: 0.343 | L7: 0.357 | M7: 0.364 | N7: 0.373 | O7: 0.381 | P7: 0.385 | Q7: 0.392 | R7: 0.388 | S7: 0.388 | T7: 0.389 | U7: 0.393 | V7: 0.398 | W7: 0.396 | X7: 0.393 | Y7: 0.394 | Z7: Africa | AA7: Emerging and Developing | AB7: 19 | AC7: =LN(_xlfn.XLOOKUP(Sheet2!A7,DataSheet!$G$2:$G$267,DataSheet!$H$2:$H$267)) -> 6.8732016
A8: MAR | B8: Morocco | C8: 0.525 | D8: 0.536 | E8: 0.547 | F8: 0.557 | G8: 0.564 | H8: 0.57 | I8: 0.576 | J8: 0.583 | K8: 0.59 | L8: 0.596 | M8: 0.604 | N8: 0.616 | O8: 0.626 | P8: 0.636 | Q8: 0.645 | R8: 0.656 | S8: 0.662 | T8: 0.671 | U8: 0.677 | V8: 0.684 | W8: 0.683 | X8: 0.688 | Y8: 0.698 | Z8: Africa | AA8: Emerging and Developing | AB8: 25 | AC8: =LN(_xlfn.XLOOKUP(Sheet2!A8,DataSheet!$G$2:$G$267,DataSheet!$H$2:$H$267)) -> 8.1499303
A9: LSO | B9: Lesotho | C9: 0.456 | D9: 0.452 | E9: 0.449 | F9: 0.45 | G9: 0.448 | H9: 0.447 | I9: 0.444 | J9: 0.45 | K9: 0.453 | L9: 0.457 | M9: 0.47 | N9: 0.478 | O9: 0.489 | P9: 0.494 | Q9: 0.5 | R9: 0.508 | S9: 0.518 | T9: 0.522 | U9: 0.525 | V9: 0.528 | W9: 0.53 | X9: 0.522 | Y9: 0.521 | Z9: Africa | AA9: Emerging and Developing | AB9: 30 | AC9: =LN(_xlfn.XLOOKUP(Sheet2!A9,DataSheet!$G$2:$G$267,DataSheet!$H$2:$H$267)) -> 6.9374362
A10: SDN | B10: Sudan | C10: 0.42 | D10: 0.428 | E10: 0.434 | F10: 0.438 | G10: 0.441 | H10: 0.448 | I10: 0.466 | J10: 0.472 | K10: 0.48 | L10: 0.489 | M10: 0.489 | N10: 0.491 | O10: 0.498 | P10: 0.503 | Q10: 0.511 | R10: 0.514 | S10: 0.517 | T10: 0.52 | U10: 0.52 | V10: 0.521 | W10: 0.518 | X10: 0.516 | Y10: 0.516 | Z10: Africa | AA10: Emerging and Developing | AB10: 32 | AC10: =LN(_xlfn.XLOOKUP(Sheet2!A10,DataSheet!$G$2:$G$267,DataSheet!$H$2:$H$267)) -> 6.9529589
A11: UGA | B11: Uganda | C11: 0.392 | D11: 0.402 | E11: 0.414 | F11: 0.427 | G11: 0.441 | H11: 0.451 | I11: 0.463 | J11: 0.473 | K11: 0.481 | L11: 0.491 | M11: 0.5 | N11: 0.504 | O11: 0.504 | P11: 0.511 | Q11: 0.518 | R11: 0.525 | S11: 0.531 | T11: 0.534 | U11: 0.539 | V11: 0.544 | W11: 0.545 | X11: 0.545 | Y11: 0.55 | Z11: Africa | AA11: Emerging and Developing | AB11: 33 | AC11: =LN(_xlfn.XLOOKUP(Sheet2!A11,DataSheet!$G$2:$G$267,DataSheet!$H$2:$H$267)) -> 6.8701233
A12: EGY | B12: Egypt | C12: 0.629 | D12: 0.633 | E12: 0.634 | F12: 0.632 | G12: 0.635 | H12: 0.637 | I12: 0.642 | J12: 0.649 | K12: 0.656 | L12: 0.661 | M12: 0.667 | N12: 0.671 | O12: 0.679 | P12: 0.684 | Q12: 0.688 | R12: 0.695 | S12: 0.702 | T12: 0.709 | U12: 0.717 | V12: 0.724 | W12: 0.729 | X12: 0.726 | Y12: 0.728 | Z12: Africa | AA12: Emerging and Developing | AB12: 34 | AC12: =LN(_xlfn.XLOOKUP(Sheet2!A12,DataSheet!$G$2:$G$267,DataSheet!$H$2:$H$267)) -> 8.350739
A13: MOZ | B13: Mozambique | C13: 0.303 | D13: 0.317 | E13: 0.325 | F13: 0.339 | G13: 0.349 | H13: 0.359 | I13: 0.367 | J13: 0.38 | K13: 0.391 | L13: 0.4 | M13: 0.407 | N13: 0.412 | O13: 0.418 | P13: 0.432 | Q13: 0.438 | R13: 0.445 | S13: 0.448 | T13: 0.45 | U13: 0.458 | V13: 0.465 | W13: 0.467 | X13: 0.459 | Y13: 0.461 | Z13: Africa | AA13: Emerging and Developing | AB13: 37 | AC13: =LN(_xlfn.XLOOKUP(Sheet2!A13,DataSheet!$G$2:$G$267,DataSheet!$H$2:$H$267)) -> 6.3600092
... A151: GUY | B151: Guyana | C151: 0.57 | D151: 0.578 | E151: 0.584 | F151: 0.591 | G151: 0.604 | H151: 0.615 | I151: 0.624 | J151: 0.631 | K151: 0.636 | L151: 0.641 | M151: 0.65 | N151: 0.663 | O151: 0.669 | P151: 0.674 | Q151: 0.682 | R151: 0.686 | S151: 0.693 | T151: 0.699 | U151: 0.704 | V151: 0.711 | W151: 0.727 | X151: 0.721 | Y151: 0.742 | Z151: South America | AA151: Emerging and Developing | AB151: 111 | AC151: =LN(_xlfn.XLOOKUP(Sheet2!A151,DataSheet!$G$2:$G$267,DataSheet!$H$2:$H$267)) -> 9.7933095

Sheet Sheet3
M3: 2013 | N3: 2014 | O3: 2015 | P3: 2016 | Q3: 2017 | R3: 2018 | S3: 2019 | T3: 2020 | U3: 2021 | V3: 2022
L4: Average | M4: =AVERAGE(Sheet2!P2:P151) -> 0.71247333 | N4: =AVERAGE(Sheet2!Q2:Q151) -> 0.71670667 | O4: =AVERAGE(Sheet2!R2:R151) -> 0.72025333 | P4: =AVERAGE(Sheet2!S2:S151) -> 0.72401333 | Q4: =AVERAGE(Sheet2!T2:T151) -> 0.72765333 | R4: =AVERAGE(Sheet2!U2:U151) -> 0.73108667 | S4: =AVERAGE(Sheet2!V2:V151) -> 0.73440667 | T4: =AVERAGE(Sheet2!W2:W151) -> 0.72994 | ... V4: =AVERAGE(Sheet2!Y2:Y151) -> 0.73374667
L5: Median | M5: =MEDIAN(Sheet2!P2:P151) -> 0.7335 | N5: =MEDIAN(Sheet2!Q2:Q151) -> 0.743 | O5: =MEDIAN(Sheet2!R2:R151) -> 0.744 | P5: =MEDIAN(Sheet2!S2:S151) -> 0.749 | Q5: =MEDIAN(Sheet2!T2:T151) -> 0.752 | R5: =MEDIAN(Sheet2!U2:U151) -> 0.752 | S5: =MEDIAN(Sheet2!V2:V151) -> 0.7545 | T5: =MEDIAN(Sheet2!W2:W151) -> 0.741 | ... V5: =MEDIAN(Sheet2!Y2:Y151) -> 0.7455
L6: IQR | M6: =QUARTILE((Sheet2!P2:P151),3) - QUARTILE((Sheet2!P2:P151), 1) -> 0.271 | N6: =QUARTILE((Sheet2!Q2:Q151),3) - QUARTILE((Sheet2!Q2:Q151), 1) -> 0.2645 | O6: =QUARTILE((Sheet2!R2:R151),3) - QUARTILE((Sheet2!R2:R151), 1) -> 0.26325 | P6: =QUARTILE((Sheet2!S2:S151),3) - QUARTILE((Sheet2!S2:S151), 1) -> 0.26025 | Q6: =QUARTILE((Sheet2!T2:T151),3) - QUARTILE((Sheet2!T2:T151), 1) -> 0.25675 | R6: =QUARTILE((Sheet2!U2:U151),3) - QUARTILE((Sheet2!U2:U151), 1) -> 0.25575 | S6: =QUARTILE((Sheet2!V2:V151),3) - QUARTILE((Sheet2!V2:V151), 1) -> 0.25575 | T6: =QUARTILE((Sheet2!W2:W151),3) - QUARTILE((Sheet2!W2:W151), 1) -> 0.2495 | ... V6: =QUARTILE((Sheet2!Y2:Y151),3) - QUARTILE((Sheet2!Y2:Y151), 1) -> 0.26375
Q15: <

Sheet Sheet4
C2: 2013 | D2: 2014 | E2: 2015 | F2: 2016 | G2: 2017 | H2: 2018 | I2: 2019 | J2: 2020 | K2: 2021 | L2: 2022
B3: Average | C3: =AVERAGE(Sheet2!P2:P151) -> 0.71247333 | D3: =AVERAGE(Sheet2!Q2:Q151) -> 0.71670667 | E3: =AVERAGE(Sheet2!R2:R151) -> 0.72025333 | F3: =AVERAGE(Sheet2!S2:S151) -> 0.72401333 | G3: =AVERAGE(Sheet2!T2:T151) -> 0.72765333 | H3: =AVERAGE(Sheet2!U2:U151) -> 0.73108667 | I3: =AVERAGE(Sheet2!V2:V151) -> 0.73440667 | J3: =AVERAGE(Sheet2!W2:W151) -> 0.72994 | ... L3: =AVERAGE(Sheet2!Y2:Y151) -> 0.73374667
B4: Lowe limit | C4: =C3-C7 -> 0.68693198 | D4: =D3-D7 -> 0.69131807 | E4: =E3-E7 -> 0.69502628 | F4: =F3-F7 -> 0.6989456 | G4: =G3-G7 -> 0.70260653 | H4: =H3-H7 -> 0.70614884 | I4: =I3-I7 -> 0.70954433 | J4: =J3-J7 -> 0.70530088 | ... L4: =L3-L7 -> 0.70864914
B5: Upper limit | C5: =C3+C7 -> 0.73801469 | D5: =D3+D7 -> 0.74209527 | E5: =E3+E7 -> 0.74548038 | F5: =F3+F7 -> 0.74908107 | G5: =G3+G7 -> 0.75270013 | H5: =H3+H7 -> 0.75602449 | I5: =I3+I7 -> 0.75926901 | J5: =J3+J7 -> 0.75457912 | ... L5: =L3+L7 -> 0.7588442
B6: Standard deviation | C6: =STDEV(Sheet2!P2:P151) -> 0.15830684 | D6: =STDEV(Sheet2!Q2:Q151) -> 0.15736008 | E6: =STDEV(Sheet2!R2:R151) -> 0.15635878 | F6: =STDEV(Sheet2!S2:S151) -> 0.15537135 | G6: =STDEV(Sheet2!T2:T151) -> 0.15524157 | H6: =STDEV(Sheet2!U2:U151) -> 0.15456616 | I6: =STDEV(Sheet2!V2:V151) -> 0.15409829 | J6: =STDEV(Sheet2!W2:W151) -> 0.15271477 | ... L6: =STDEV(Sheet2!Y2:Y151) -> 0.15555599
B7: Error | C7: =_xlfn.CONFIDENCE.T(0.05, C6, 150) -> 0.025541353 | D7: =_xlfn.CONFIDENCE.T(0.05, D6, 150) -> 0.025388601 | E7: =_xlfn.CONFIDENCE.T(0.05, E6, 150) -> 0.025227051 | F7: =_xlfn.CONFIDENCE.T(0.05, F6, 150) -> 0.025067737 | G7: =_xlfn.CONFIDENCE.T(0.05, G6, 150) -> 0.0250468 | H7: =_xlfn.CONFIDENCE.T(0.05, H6, 150) -> 0.024937828 | I7: =_xlfn.CONFIDENCE.T(0.05, I6, 150) -> 0.024862342 | J7: =_xlfn.CONFIDENCE.T(0.05, J6, 150) -> 0.024639124 | ... L7: =_xlfn.CONFIDENCE.T(0.05, L6, 150) -> 0.025097528

Sheet Sheet5
B3: H₀: μ = 0.695 (the average HDI in the sample is equal to the IMF value) | I3: 2013 | J3: 2022
B4: H₁: μ ≠ 0.695 (the average HDI is different) | H4: Average | I4: =AVERAGE(Sheet2!P2:P151) -> 0.71247333 | J4: =AVERAGE(Sheet2!Y2:Y151) -> 0.73374667
B5: μ | C5: 0.695 | H5: Standard deviation | I5: =STDEV(Sheet2!P2:P151) -> 0.15830684 | J5: =STDEV(Sheet2!Y2:Y151) -> 0.15555599
H6: t-statistics | I6: =(I4-C5)/(I5/SQRT(150)) -> 1.3518288 | J6: =(J4-C5)/(J5/SQRT(150)) -> 3.0506559
H7: p-value | I7: =_xlfn.T.DIST.2T(ABS(I6),149) -> 0.17847862 | J7: =_xlfn.T.DIST.2T(ABS(J6),149) -> 0.002703738
H8: t-critical | I8: =_xlfn.T.INV.2T(0.05,149) -> 1.9760132 | J8: =_xlfn.T.INV.2T(0.05,149) -> 1.9760132

Sheet Sheet6
B3: H₀: μ_d = 0 (mean of differences HDI 2022 − 2013 = 0) | G3: Difference = hdi_2022 − hdi_2013
B4: H₁: μ_d > 0 (HDI 2022 is higher than 2013) | G4: Equatorial Guinea | H4: =Sheet2!Y2-Sheet2!P2 -> 0.017 | J4: Mean of differences | K4: =AVERAGE(H4:H153) -> 0.021273333
G5: Libya | H5: =Sheet2!Y3-Sheet2!P3 -> -0.02 | J5: Standard deviation of the means | K5: =STDEV(H4:H153) -> 0.023010035
G6: Togo | H6: =Sheet2!Y4-Sheet2!P4 -> 0.052 | J6: t-statistic | K6: =K4/(K5/SQRT(150)) -> 11.323062
G7: Ghana | H7: =Sheet2!Y5-Sheet2!P5 -> 0.015 | J7: p-value | K7: =_xlfn.T.DIST.RT(K6,149) -> 3.8963683e-22
G8: Ethiopia | H8: =Sheet2!Y6-Sheet2!P6 -> 0.055 | J8: t-critical | K8: =_xlfn.T.INV(0.95,149) -> 1.6551445
G9: Chad | H9: =Sheet2!Y7-Sheet2!P7 -> 0.009
G10: Morocco | H10: =Sheet2!Y8-Sheet2!P8 -> 0.062 | J10: T.test (p-value) | K10: =_xlfn.T.TEST(Sheet2!P2:P151,Sheet2!Y2:Y151,1,1) -> 3.8963683e-22
G11: Lesotho | H11: =Sheet2!Y9-Sheet2!P9 -> 0.027
G12: Sudan | H12: =Sheet2!Y10-Sheet2!P10 -> 0.013
G13: Uganda | H13: =Sheet2!Y11-Sheet2!P11 -> 0.039
G14: Egypt | H14: =Sheet2!Y12-Sheet2!P12 -> 0.044
G15: Mozambique | H15: =Sheet2!Y13-Sheet2!P13 -> 0.029
G16: Central African Republic | H16: =Sheet2!Y14-Sheet2!P14 -> 0.035
G17: Kenya | H17: =Sheet2!Y15-Sheet2!P15 -> 0.039
G18: Comoros | H18: =Sheet2!Y16-Sheet2!P16 -> 0.04
G19: Sao Tome and Principe | H19: =Sheet2!Y17-Sheet2!P17 -> 0.04
G20: Gambia | H20: =Sheet2!Y18-Sheet2!P18 -> 0.034
G21: Djibouti | H21: =Sheet2!Y19-Sheet2!P19 -> 0.062
G22: Algeria | H22: =Sheet2!Y20-Sheet2!P20 -> 0.016
... G153: Guyana | H153: =Sheet2!Y151-Sheet2!P151 -> 0.068

Sheet Sheet7
C2: 2013 | D2: 2014 | E2: 2015 | F2: 2016 | G2: 2017 | H2: 2018 | I2: 2019 | J2: 2020 | K2: 2021 | L2: 2022
B3: Europe | C3: =AVERAGEIF(Sheet2!$Z$2:$Z$151, "Europe",Sheet2!P2:P151) -> 0.87358824 | D3: =AVERAGEIF(Sheet2!$Z$2:$Z$151, "Europe",Sheet2!Q2:Q151) -> 0.87735294 | E3: =AVERAGEIF(Sheet2!$Z$2:$Z$151, "Europe",Sheet2!R2:R151) -> 0.87879412 | F3: =AVERAGEIF(Sheet2!$Z$2:$Z$151, "Europe",Sheet2!S2:S151) -> 0.88179412 | G3: =AVERAGEIF(Sheet2!$Z$2:$Z$151, "Europe",Sheet2!T2:T151) -> 0.88502941 | H3: =AVERAGEIF(Sheet2!$Z$2:$Z$151, "Europe",Sheet2!U2:U151) -> 0.88741176 | I3: =AVERAGEIF(Sheet2!$Z$2:$Z$151, "Europe",Sheet2!V2:V151) -> 0.89085294 | J3: =AVERAGEIF(Sheet2!$Z$2:$Z$151, "Europe",Sheet2!W2:W151) -> 0.88508824 | ... L3: =AVERAGEIF(Sheet2!$Z$2:$Z$151, "Europe",Sheet2!Y2:Y151) -> 0.89088235
B4: Africa | C4: =AVERAGEIF(Sheet2!$Z$2:$Z$151, "Africa",Sheet2!P2:P151) -> 0.54314634 | D4: =AVERAGEIF(Sheet2!$Z$2:$Z$151, "Africa",Sheet2!Q2:Q151) -> 0.54860976 | E4: =AVERAGEIF(Sheet2!$Z$2:$Z$151, "Africa",Sheet2!R2:R151) -> 0.55404878 | F4: =AVERAGEIF(Sheet2!$Z$2:$Z$151, "Africa",Sheet2!S2:S151) -> 0.55887805 | G4: =AVERAGEIF(Sheet2!$Z$2:$Z$151, "Africa",Sheet2!T2:T151) -> 0.56358537 | H4: =AVERAGEIF(Sheet2!$Z$2:$Z$151, "Africa",Sheet2!U2:U151) -> 0.56780488 | I4: =AVERAGEIF(Sheet2!$Z$2:$Z$151, "Africa",Sheet2!V2:V151) -> 0.572 | J4: =AVERAGEIF(Sheet2!$Z$2:$Z$151, "Africa",Sheet2!W2:W151) -> 0.56978049 | ... L4: =AVERAGEIF(Sheet2!$Z$2:$Z$151, "Africa",Sheet2!Y2:Y151) -> 0.57107317
